Workbook

Sheet Data
U1: 2020
A2: 23560036 | B2: น.ส. | C2: ทิชากร | D2: ศรีจำปา | E2: Miss Tichakorn Srichampa | F2: Administration Officer | G2: พนักงานบริหารงาน | H2: AFM | J2: ส่วนกลยุทธ์และบริหารทรัพยากรอาคารฯ | L2: ฝ่ายบริหารทรัพยากรอาคาร | N2: สายงานประธานเจ้าหน้าที่ปฏิบัติการ | O2: ปธบ.และกรรมการผู้จัดการใหญ่ | P2: GPSC Rayong | Q2: GPSC RYG : CUP-2 | R2: GPSC CUP2-F | S2: FLEXIBLE2 | T2: Female | U2: 0897494028
A3: 23560043 | B3: น.ส. | C3: บงกช | D3: ยุทธวิสุทธิ | E3: Miss Bongkot Yootawisuti | F3: Senior Administration Officer | G3: พนักงานบริหารงานอาวุโส | H3: AFM | J3: ส่วนกลยุทธ์และบริหารทรัพยากรอาคารฯ | L3: ฝ่ายบริหารทรัพยากรอาคาร | N3: สายงานประธานเจ้าหน้าที่ปฏิบัติการ | O3: ปธบ.และกรรมการผู้จัดการใหญ่ | P3: GPSC Rayong | Q3: GPSC RYG : CUP-2 | R3: GPSC CUP2-F | S3: FLEXIBLE2 | T3: Female
A4: 23560092 | B4: นาย | C4: ภาณุ | D4: โพธิกุล | E4: Mr. Panu Potikul | F4: Facility Management Strategy and Site General Services Division Manager | G4: ผู้จัดการส่วนกลยุทธ์และบริหารทรัพยากรอาคารพื้นที่ปฏิบัติการ | H4: AFM | J4: ส่วนกลยุทธ์และบริหารทรัพยากรอาคารฯ | L4: ฝ่ายบริหารทรัพยากรอาคาร | N4: สายงานประธานเจ้าหน้าที่ปฏิบัติการ | O4: ปธบ.และกรรมการผู้จัดการใหญ่ | P4: GPSC Bangkok | Q4: GPSC RYG : CUP-2 | R4: GPSC HO-F | S4: FLEXIBLE2 | T4: Male
A5: 23560177 | B5: น.ส. | C5: จามจุรี | D5: เกษรสวัสดิ์ | E5: Miss Jamjuree Kasonsavad | F5: Administration Officer | G5: พนักงานบริหารงาน | H5: AFM | J5: ส่วนกลยุทธ์และบริหารทรัพยากรอาคารฯ | L5: ฝ่ายบริหารทรัพยากรอาคาร | N5: สายงานประธานเจ้าหน้าที่ปฏิบัติการ | O5: ปธบ.และกรรมการผู้จัดการใหญ่ | P5: GPSC Rayong | Q5: GPSC RYG : CUP-2 | R5: GPSC CUP2-F | S5: FLEXIBLE2 | T5: Female
A6: 23560197 | B6: นาย | C6: ณรงค์ชัย | D6: พรหมเดชวัฒนา | E6: Mr. Narongchai Promdetwattana | F6: Administration Officer | G6: พนักงานบริหารงาน | H6: AFM | J6: ส่วนกลยุทธ์และบริหารทรัพยากรอาคารฯ | L6: ฝ่ายบริหารทรัพยากรอาคาร | N6: สายงานประธานเจ้าหน้าที่ปฏิบัติการ | O6: ปธบ.และกรรมการผู้จัดการใหญ่ | P6: GPSC Rayong | Q6: GPSC RYG : CUP-2 | R6: GPSC CUP2-F | S6: FLEXIBLE2 | T6: Male | U6: 0905492561
A7: 23630027 | B7: นาง | C7: อุษิตตา | D7: มาลย์มาศภาณุ | E7: Mrs. Usitta Marlmaspanu | F7: Site General Administration Manager | G7: ผู้จัดการบริหารสำนักงานพื้นที่ปฏิบัติการ | H7: AFM | J7: ส่วนกลยุทธ์และบริหารทรัพยากรอาคารฯ | L7: ฝ่ายบริหารทรัพยากรอาคาร | N7: สายงานประธานเจ้าหน้าที่ปฏิบัติการ | O7: ปธบ.และกรรมการผู้จัดการใหญ่ | P7: GPSC Rayong | Q7: GPSC RYG : SPP2/3 | R7: GPSC SPP2/3-F | S7: FLEXIBLE2 | T7: Female | U7: 089-2059179
A8: 23630050 | B8: นาย | C8: บุญชนะ | D8: อินทรโชติ | E8: Mr. Boonchana Intarachote | F8: Administration Officer | G8: พนักงานบริหารงาน | H8: AFM | J8: ส่วนกลยุทธ์และบริหารทรัพยากรอาคารฯ | L8: ฝ่ายบริหารทรัพยากรอาคาร | N8: สายงานประธานเจ้าหน้าที่ปฏิบัติการ | O8: ปธบ.และกรรมการผู้จัดการใหญ่ | P8: GPSC Rayong | Q8: GPSC RYG : SPP2/3 | R8: GPSC SPP2/3-F | S8: FLEXIBLE2 | T8: Male
A9: 23630114 | B9: นาง | C9: พิมลพรรณ | D9: สุวรรณรัตน์ | E9: Mrs. Pimonparn Suwannarat | F9: Administration Officer | G9: พนักงานบริหารงาน | H9: AFM | J9: ส่วนกลยุทธ์และบริหารทรัพยากรอาคารฯ | L9: ฝ่ายบริหารทรัพยากรอาคาร | N9: สายงานประธานเจ้าหน้าที่ปฏิบัติการ | O9: ปธบ.และกรรมการผู้จัดการใหญ่ | P9: GPSC Rayong | Q9: GPSC RYG : SPP2/3 | R9: GPSC SPP2/3-F | S9: FLEXIBLE2 | T9: Female
A10: 23630203 | B10: น.ส. | C10: พาฝัน | D10: ผลดี | E10: Miss Pafhan Pholdee | F10: Administration Officer | G10: พนักงานบริหารงาน | H10: AFM | J10: ส่วนกลยุทธ์และบริหารทรัพยากรอาคารฯ | L10: ฝ่ายบริหารทรัพยากรอาคาร | N10: สายงานประธานเจ้าหน้าที่ปฏิบัติการ | O10: ปธบ.และกรรมการผู้จัดการใหญ่ | P10: GPSC Rayong | Q10: GPSC RYG : SPP2/3 | R10: GPSC SPP2/3-F | S10: FLEXIBLE2 | T10: Female
A11: 23630300 | B11: น.ส. | C11: วรัญญา | D11: มังสังคำ | E11: Miss Waranya Mangsangkam | F11: Administration Officer | G11: พนักงานบริหารงาน | H11: AFM | J11: ส่วนกลยุทธ์และบริหารทรัพยากรอาคารฯ | L11: ฝ่ายบริหารทรัพยากรอาคาร | N11: สายงานประธานเจ้าหน้าที่ปฏิบัติการ | O11: ปธบ.และกรรมการผู้จัดการใหญ่ | P11: GPSC Rayong | Q11: GPSC RYG : SPP2/3 | R11: GPSC SPP2/3-F | S11: FLEXIBLE2 | T11: Female
A12: 23630301 | B12: นาย | C12: ธนาธร | D12: ก่ำแก้ว | E12: Mr. Thanathorn Kamkaew | F12: Administration Officer | G12: พนักงานบริหารงาน | H12: AFM | J12: ส่วนกลยุทธ์และบริหารทรัพยากรอาคารฯ | L12: ฝ่ายบริหารทรัพยากรอาคาร | N12: สายงานประธานเจ้าหน้าที่ปฏิบัติการ | O12: ปธบ.และกรรมการผู้จัดการใหญ่ | P12: GPSC Rayong | Q12: GPSC RYG : SPP2/3 | R12: GPSC SPP2/3-F | S12: FLEXIBLE2 | T12: Male
A13: 23630142 | B13: นาง | C13: มัณทนา | D13: คุณากร | E13: Mrs. Mantana Kunakorn | F13: Senior Vice President Group Facility Management | G13: ผู้จัดการฝ่ายอาวุโสบริหารทรัพยากรอาคาร | H13: AFS | M13: ฝ่ายบริหารทรัพยากรอาคาร | N13: สายงานประธานเจ้าหน้าที่ปฏิบัติการ | O13: บริษัท ปตท. จำกัด (มหาชน) | P13: GPSC Bangkok | Q13: GPSC BKK : Empire Tower - 38th floor | R13: GPSC HO-F | S13: FLEXIBLE4 | T13: Female | U13: 089-2057073
A14: 23630033 | B14: นาง | C14: บัวลอย | D14: เคียนขุนทด | E14: Mrs. Bualoi Kienkhuntod | F14: Maid | G14: แม่บ้าน | H14: AGT | I14: แผนกบริหารสำนักงานและบริหารงานทั่วไป | L14: ฝ่ายบริหารทรัพยากรอาคาร | N14: สายงานประธานเจ้าหน้าที่ปฏิบัติการ | O14: ปธบ.และกรรมการผู้จัดการใหญ่ | P14: GPSC Bangkok | Q14: GPSC BKK : Empire Tower - 38th floor | R14: GPSC HO-F | S14: FLEXIBLE4 | T14: Female
A15: 23630039 | B15: นาง | C15: พรทิพย์ | D15: ชุมนุม | E15: Mrs. Porntip Chumnum | F15: Administration Officer | G15: พนักงานบริหารงาน | H15: AGT | I15: แผนกบริหารสำนักงานและบริหารงานทั่วไป | L15: ฝ่ายบริหารทรัพยากรอาคาร | N15: สายงานประธานเจ้าหน้าที่ปฏิบัติการ | O15: ปธบ.และกรรมการผู้จัดการใหญ่ | P15: GPSC Bangkok | Q15: GPSC BKK : Empire Tower - 38th floor | R15: GPSC HO-F | S15: FLEXIBLE4 | T15: Female | U15: 081-3758406
A16: 23630048 | B16: นาย | C16: ไชยา | D16: จันทร์คง | E16: Mr. Chaiya Chankong | F16: Driver | G16: พนักงานขับรถ | H16: AGT | I16: แผนกบริหารสำนักงานและบริหารงานทั่วไป | L16: ฝ่ายบริหารทรัพยากรอาคาร | N16: สายงานประธานเจ้าหน้าที่ปฏิบัติการ | O16: ปธบ.และกรรมการผู้จัดการใหญ่ | P16: GPSC Bangkok | Q16: GPSC BKK : Empire Tower - 38th floor | R16: GPSC HO-F | S16: FLEXIBLE4 | T16: Male
A17: 23630049 | B17: นาง | C17: วงเดือน | D17: จันปัญญา | E17: Mrs. Wongduen Junpunya | F17: Maid | G17: แม่บ้าน | H17: AGT | I17: แผนกบริหารสำนักงานและบริหารงานทั่วไป | L17: ฝ่ายบริหารทรัพยากรอาคาร | N17: สายงานประธานเจ้าหน้าที่ปฏิบัติการ | O17: ปธบ.และกรรมการผู้จัดการใหญ่ | P17: GPSC Bangkok | Q17: GPSC BKK : Empire Tower - 38th floor | R17: GPSC HO-F | S17: FLEXIBLE4 | T17: Female
A18: 23630127 | B18: นาย | C18: วิเชียร | D18: ปู่เจ๊ก | E18: Mr. Wichein Pujek | F18: Driver | G18: พนักงานขับรถ | H18: AGT | I18: แผนกบริหารสำนักงานและบริหารงานทั่วไป | L18: ฝ่ายบริหารทรัพยากรอาคาร | N18: สายงานประธานเจ้าหน้าที่ปฏิบัติการ | O18: ปธบ.และกรรมการผู้จัดการใหญ่ | P18: GPSC Bangkok | Q18: GPSC BKK : Empire Tower - 38th floor | R18: GPSC HO-F | S18: FLEXIBLE4 | T18: Male
A19: 23630132 | B19: น.ส. | C19: นงลักษณ์ | D19: ชิตมณี | E19: Miss Nonglak Chitmanee | F19: Administration Officer | G19: พนักงานบริหารงาน | H19: AGT | I19: แผนกบริหารสำนักงานและบริหารงานทั่วไป | L19: ฝ่ายบริหารทรัพยากรอาคาร | N19: สายงานประธานเจ้าหน้าที่ปฏิบัติการ | O19: ปธบ.และกรรมการผู้จัดการใหญ่ | P19: GPSC Bangkok | Q19: GPSC BKK : Empire Tower - 38th floor | R19: GPSC HO-F | S19: FLEXIBLE4 | T19: Female | U19: 085-6605019
A20: 23630159 | B20: นาย | C20: สุรศักดิ์ | D20: สูญสิ้นภัย | E20: Mr. Surasak Soonsinpai | F20: Driver | G20: พนักงานขับรถ | H20: AGT | I20: แผนกบริหารสำนักงานและบริหารงานทั่วไป | L20: ฝ่ายบริหารทรัพยากรอาคาร | N20: สายงานประธานเจ้าหน้าที่ปฏิบัติการ | O20: ปธบ.และกรรมการผู้จัดการใหญ่ | P20: GPSC Bangkok | Q20: GPSC BKK : Empire Tower - 38th floor | R20: GPSC HO-F | S20: FLEXIBLE4 | T20: Male
A21: 23630160 | B21: นาย | C21: ธวัช | D21: ภูมิสัทธรรม | E21: Mr. Thawat Phumisatthatham | F21: Driver | G21: พนักงานขับรถ | H21: AGT | I21: แผนกบริหารสำนักงานและบริหารงานทั่วไป | L21: ฝ่ายบริหารทรัพยากรอาคาร | N21: สายงานประธานเจ้าหน้าที่ปฏิบัติการ | O21: ปธบ.และกรรมการผู้จัดการใหญ่ | P21: GPSC Bangkok | Q21: GPSC BKK : Empire Tower - 38th floor | R21: GPSC HO-F | S21: FLEXIBLE4 | T21: Male
A22: 23630171 | B22: นาย | C22: ขาว | D22: ไชยวงค์สาย | E22: Mr. Khao Chaiwongsai | F22: Driver | G22: พนักงานขับรถ | H22: AGT | I22: แผนกบริหารสำนักงานและบริหารงานทั่วไป | L22: ฝ่ายบริหารทรัพยากรอาคาร | N22: สายงานประธานเจ้าหน้าที่ปฏิบัติการ | O22: ปธบ.และกรรมการผู้จัดการใหญ่ | P22: GPSC Bangkok | Q22: GPSC BKK : Empire Tower - 38th floor | R22: GPSC HO-F | S22: FLEXIBLE4 | T22: Male
A23: 23630238 | B23: น.ส. | C23: ณัฐธดา | D23: ธนอัศวกุล | E23: Miss Natthada Thana-assavakul | F23: Office Management and General Services Section Manager | G23: ผู้จัดการแผนกบริหารสำนักงานและบริหารงานทั่วไป | H23: AGT | I23: แผนกบริหารสำนักงานและบริหารงานทั่วไป | L23: ฝ่ายบริหารทรัพยากรอาคาร | N23: สายงานประธานเจ้าหน้าที่ปฏิบัติการ | O23: ปธบ.และกรรมการผู้จัดการใหญ่ | P23: GPSC Bangkok | Q23: GPSC BKK : Empire Tower - 38th floor | R23: GPSC HO-F | S23: FLEXIBLE4 | T23: Female | U23: 084-4390076
A24: 23630243 | B24: นาย | C24: ธีรวัฒน์ | D24: จิรวัฒโนบล | E24: Mr. Teerawat Jirawatnobon | F24: Driver | G24: พนักงานขับรถ | H24: AGT | I24: แผนกบริหารสำนักงานและบริหารงานทั่วไป | L24: ฝ่ายบริหารทรัพยากรอาคาร | N24: สายงานประธานเจ้าหน้าที่ปฏิบัติการ | O24: ปธบ.และกรรมการผู้จัดการใหญ่ | P24: GPSC Bangkok | Q24: GPSC BKK : Empire Tower - 38th floor | R24: GPSC HO-F | S24: FLEXIBLE4 | T24: Male
A25: 23630340 | B25: นาย | C25: ธันวา | D25: ทองคงแก้ว | E25: Mr. Thanwa Thongkongkaew | F25: Driver | G25: พนักงานขับรถ | H25: AGT | I25: แผนกบริหารสำนักงานและบริหารงานทั่วไป | L25: ฝ่ายบริหารทรัพยากรอาคาร | N25: สายงานประธานเจ้าหน้าที่ปฏิบัติการ | O25: ปธบ.และกรรมการผู้จัดการใหญ่ | P25: GPSC Bangkok | Q25: GPSC BKK : Empire Tower - 38th floor | R25: GPSC HO-F | S25: FLEXIBLE4 | T25: Male
A26: 23630023 | B26: นาย | C26: บุญเลิศ | D26: เพ็ชรผุดผ่อง | E26: Mr. Boonlert Petputpong | F26: Driver | G26: พนักงานขับรถ | H26: AGT | I26: แผนกบริหารสำนักงานและบริหารงานทั่วไป | L26: ฝ่ายบริหารทรัพยากรอาคาร | N26: สายงานประธานเจ้าหน้าที่ปฏิบัติการ | O26: ปธบ.และกรรมการผู้จัดการใหญ่ | P26: GPSC Chonburi | Q26: GPSC CBI : GIPP | R26: GPSC GIPP-F | S26: FLEXIBLE2 | T26: Male
A27: 23630064 | B27: นาย | C27: ศราวุธ | D27: ชื่นบาน | E27: Mr. Sarawut Choenban | F27: Driver | G27: พนักงานขับรถ | H27: AGT | I27: แผนกบริหารสำนักงานและบริหารงานทั่วไป | L27: ฝ่ายบริหารทรัพยากรอาคาร | N27: สายงานประธานเจ้าหน้าที่ปฏิบัติการ | O27: ปธบ.และกรรมการผู้จัดการใหญ่ | P27: GPSC Chonburi | Q27: GPSC RYG : SPP11 | R27: GPSC GIPP-F | S27: FLEXIBLE2 | T27: Male
A28: 23630024 | B28: นาย | C28: มาโนช | D28: พูลเล็ก | E28: Mr. Manoch Poollake | F28: Driver | G28: พนักงานขับรถ | H28: AGT | I28: แผนกบริหารสำนักงานและบริหารงานทั่วไป | L28: ฝ่ายบริหารทรัพยากรอาคาร | N28: สายงานประธานเจ้าหน้าที่ปฏิบัติการ | O28: ปธบ.และกรรมการผู้จัดการใหญ่ | P28: GPSC Rayong | Q28: GPSC RYG : SPP2/3 | R28: GPSC SPP2/3-F | S28: FLEXIBLE2 | T28: Male
A29: 23630091 | B29: นาย | C29: คำมี | D29: อันทปัญญา | E29: Mr. Kammee Anthapanya | F29: Driver | G29: พนักงานขับรถ | H29: AGT | I29: แผนกบริหารสำนักงานและบริหารงานทั่วไป | L29: ฝ่ายบริหารทรัพยากรอาคาร | N29: สายงานประธานเจ้าหน้าที่ปฏิบัติการ | O29: ปธบ.และกรรมการผู้จัดการใหญ่ | P29: GPSC Rayong | Q29: GPSC RYG : SPP2/3 | R29: GPSC SPP2/3-F | S29: FLEXIBLE2 | T29: Male
A30: 23630128 | B30: นาย | C30: ประนุ | D30: เทินเกษม | E30: Mr. Pranu Terngasem | F30: Driver | G30: พนักงานขับรถ | H30: AGT | I30: แผนกบริหารสำนักงานและบริหารงานทั่วไป | L30: ฝ่ายบริหารทรัพยากรอาคาร | N30: สายงานประธานเจ้าหน้าที่ปฏิบัติการ | O30: ปธบ.และกรรมการผู้จัดการใหญ่ | P30: GPSC Bangkok | Q30: GPSC RYG : SPP2/3 | R30: GPSC HO-F | S30: FLEXIBLE4 | T30: Male
A31: 23630169 | B31: นาย | C31: ประเดิมชัย | D31: โด่งดัง | E31: Mr. Pradermchai Dongdang | F31: Driver | G31: พนักงานขับรถ | H31: AGT | I31: แผนกบริหารสำนักงานและบริหารงานทั่วไป | L31: ฝ่ายบริหารทรัพยากรอาคาร | N31: สายงานประธานเจ้าหน้าที่ปฏิบัติการ | O31: ปธบ.และกรรมการผู้จัดการใหญ่ | P31: GPSC Rayong | Q31: GPSC RYG : SPP2/3 | R31: GPSC SPP2/3-F | S31: FLEXIBLE2 | T31: Male
A32: 23630170 | B32: นาย | C32: ชำนาญ | D32: บัวนาค | E32: Mr. Chumnan Buanak | F32: Driver | G32: พนักงานขับรถ | H32: AGT | I32: แผนกบริหารสำนักงานและบริหารงานทั่วไป | L32: ฝ่ายบริหารทรัพยากรอาคาร | N32: สายงานประธานเจ้าหน้าที่ปฏิบัติการ | O32: ปธบ.และกรรมการผู้จัดการใหญ่ | P32: GPSC Rayong | Q32: GPSC RYG : SPP2/3 | R32: GPSC SPP2/3-F | S32: FLEXIBLE2 | T32: Male
A33: 23630226 | B33: นาย | C33: อานนท์ | D33: อินศร | E33: Mr. Anon Insorn | F33: Driver | G33: พนักงานขับรถ | H33: AGT | I33: แผนกบริหารสำนักงานและบริหารงานทั่วไป | L33: ฝ่ายบริหารทรัพยากรอาคาร | N33: สายงานประธานเจ้าหน้าที่ปฏิบัติการ | O33: ปธบ.และกรรมการผู้จัดการใหญ่ | P33: GPSC Rayong | Q33: GPSC RYG : SPP2/3 | R33: GPSC SPP2/3-F | S33: FLEXIBLE2 | T33: Male
A34: 23630368 | B34: น.ส. | C34: ตรีชฎา | D34: กิ่งป้อง | E34: Miss Trechada Kingpong | F34: Receptionist | G34: พนักงานต้อนรับ | H34: AGT | I34: แผนกบริหารสำนักงานและบริหารงานทั่วไป | L34: ฝ่ายบริหารทรัพยากรอาคาร | N34: สายงานประธานเจ้าหน้าที่ปฏิบัติการ | O34: ปธบ.และกรรมการผู้จัดการใหญ่ | P34: GPSC Rayong | Q34: GPSC RYG : SPP2/3 | R34: GPSC SPP2/3-F | S34: FLEXIBLE2 | T34: Female
A35: 23630415 | B35: น.ส. | C35: รวิสรา | D35: รุ่งโรจน์ | E35: Miss Rawisara Rungrot | F35: Receptionist | G35: พนักงานต้อนรับ | H35: AGT | I35: แผนกบริหารสำนักงานและบริหารงานทั่วไป | L35: ฝ่ายบริหารทรัพยากรอาคาร | N35: สายงานประธานเจ้าหน้าที่ปฏิบัติการ | O35: ปธบ.และกรรมการผู้จัดการใหญ่ | P35: GPSC Rayong | Q35: GPSC RYG : SPP2/3 | R35: GPSC SPP2/3-F | S35: FLEXIBLE2 | T35: Female
A36: 23620052 | B36: นาง | C36: รสยา | D36: เธียรวรรณ | E36: Mrs. Rosaya Teinwan | F36: Executive Vice President - Business Development | G36: รองกรรมการผู้จัดการใหญ่พัฒนาธุรกิจ | H36: BDE | O36: บริษัท ปตท. จำกัด (มหาชน) | P36: GPSC Bangkok | Q36: GPSC BKK : EnCo B - 18th floor | R36: GPSC HO-F | S36: FLEXIBLE4 | T36: Female
A37: 23630467 | B37: น.ส. | C37: อัสนา | D37: มั่นปกป้อง | E37: Miss Atsana Monpokpong | F37: Secretary | G37: เลขานุการ | H37: BDE | O37: บริษัท ปตท. จำกัด (มหาชน) | P37: GPSC Bangkok | Q37: GPSC BKK : EnCo B - 18th floor | R37: GPSC HO-F | S37: FLEXIBLE1 | T37: Female
A38: 23600027 | B38: นาย | C38: กฤตภาส | D38: วารี | E38: Mr. Krittaphat Waree | F38: Senior Engineer | G38: วิศวกรอาวุโส | H38: BFS | M38: สายงานรองกผญ.พัฒนาธุรกิจ | O38: บริษัท ปตท. จำกัด (มหาชน) | P38: GPSC Rayong | Q38: GPSC BKK : EnCo B - 5th floor | R38: GPSC CUP2-F | S38: FLEXIBLE4 | T38: Male | U38: 0979188063
A39: 23600037 | B39: น.ส. | C39: พิมพ์นภัส | D39: อุตมชาติวัฒน์ | E39: Miss Phimnaphat Utamachatiwat | F39: Division Manager | G39: ผู้จัดการส่วน | H39: BFS | M39: สายงานรองกผญ.พัฒนาธุรกิจ | O39: บริษัท ปตท. จำกัด (มหาชน) | P39: GPSC Bangkok | Q39: GPSC BKK : EnCo B - 5th floor | R39: GPSC HO-F | S39: FLEXIBLE4 | T39: Female
A40: 23630013 | B40: น.ส. | C40: นนทวรรณ | D40: อำนวยมัจฉา | E40: Miss Nontawan Amnuaymucha | F40: Engineer | G40: วิศวกร | H40: BFS | M40: สายงานรองกผญ.พัฒนาธุรกิจ | O40: บริษัท ปตท. จำกัด (มหาชน) | P40: GPSC Rayong | Q40: GPSC BKK : EnCo B - 5th floor | R40: GPSC CUP2-F | S40: FLEXIBLE1 | T40: Female
...

Sheet Risk Criteria (TH)
B1: GPSC Risk Criteria
G2: (Version as of 7 Aug 2019)
B3: เกณฑ์การประเมินโอกาสเกิด (Likelihood) | D3: ระดับ
D4: ต่ำ 1 | E4: ปานกลาง 2 | F4: สูง 3 | G4: รุนแรง 4
B6: โอกาสเกิด | D6: < 10% | E6: >10% ถึง < 20% | F6: >20% ถึง < 50% | G6: > 50%
D7: ไม่เคย/เคยเกิดขึ้น 1 ครั้งใน 5 ปี | E7: เคยเกิดขึ้น 1 ครั้ง ใน 3 ปี | F7: เคยเกิดขึ้น 1 ครั้ง ใน 1 ปี | G7: เคยเกิดขึ้น > 1 ครั้ง ใน 1 ปี
B9: เกณฑ์การประเมินผลกระทบ (Impact) | D9: ระดับ
D10: ต่ำ 1 | E10: ปานกลาง 2 | F10: สูง 3 | G10: รุนแรง 4
B11: ด้านการเงิน (Financial) | C11: กำไรสุทธิต่ำกว่าเป้าหมาย (Net Profit) | D11: < 1.25% | E11: > 1.25% ถึง < 2.5% | F11: > 2.5% ถึง < 5% | G11: > 5%
C12: กำไรขั้นต้นต่ำกว่าเป้าหมาย (EBITDA) | D12: < 1.25% | E12: > 1.25% ถึง < 2.5% | F12: > 2.5% ถึง < 5% | G12: > 5%
C13: รายได้ต่ำกว่าเป้าหมาย (Revenue) | D13: < 1.25% | E13: > 1.25% ถึง < 2.5% | F13: > 2.5% ถึง < 5% | G13: > 5%
C14: ค่าใช้จ่ายสูงกว่าเป้าหมาย (Expense) | D14: < 1.25% | E14: > 1.25% ถึง < 2.5% | F14: > 2.5% ถึง < 5% | G14: > 5%
C15: ผลตอบแทนการลงทุนต่ำกว่าเป้าหมาย (Project Return: Equity IRR) | D15: < 5 % จาก base case | E15: > 5 % ถึง < 10 % จาก base case | F15: > 10% ถึง < 15% จาก base case | G15: >15 % จาก base case
C16: งบประมาณลงทุนสูงกว่าที่ได้รับอนุมัติ (Project Cost Overrun) | D16: < 1.25%จาก base case | E16: > 1.25% ถึง < 2.5% จาก base case | F16: > 2.5% ถึง < 5% จาก base case | G16: > 5% จาก base case
B17: ด้านกระบวนการธุรกิจ และการปฏิบัติการ (Business Process and Operation ) | C17: ประสิทธิผลของกระบวนการ | D17: มีผลกระทบต่อกระบวนการผลิต/กระบวนการดำเนินงานเล็กน้อยโดยอยู่ในระดับที่สามารถควบคุมและแก้ไขได้ด้วยตนเอง | E17: มีผลกระทบต่อกระบวนการผลิต/กระบวนการดำเนินงาน โดยอยู่ในระดับที่สามารถควบคุมและแก้ไขได้โดยหน่วยงานที่เกี่ยวข้อง | F17: มีผลกระทบต่อกระบวนการผลิต/กระบวนการดำเนินงาน โดยจำเป็นต้องหยุด/ชะลอการดำเนินงานหลักบางส่วนลง | G17: มีผลกระทบต่อกระบวนการผลิต/กระบวนการดำเนินงานอย่างรุนแรง โดยส่งผลกระทบต่อการส่งมอบผลิตภัณฑ์แก่ลูกค้า/การดำเนินงานและเป้าหมายตามแผนงาน
C18: ผลิตภัณฑ์หรือบริการ | D18: เกิดความล่าช้าในการส่งมอบผลิตภัณฑ์/บริการ | E18: เกิดความล่าช้าในการส่งมอบผลิตภัณฑ์/บริการ และไม่ได้คุณภาพตรงตามข้อกำหนด | F18: ไม่สามารถผลิต/ส่งมอบผลิตภัณฑ์หรือบริการได้ | G18: ไม่สามารถผลิต/ส่งมอบผลิตภัณฑ์หรือบริการและบริษัทมีค่าใช้จ่ายส่วนเพิ่มหรือถูกเรียกร้องค่าเสียหาย
C19: การปฏิบัติตามกฎหมาย / กฎระเบียบ / ข้อบังคับ | D19: ขัดต่อกฎระเบียบ/ข้อบังคับ/ข้อกำหนดตามมาตรฐานต่างๆ ของบริษัท | E19: ขัดต่อกฎหมาย กฏระเบียบของหน่วยงานภายนอกที่กำกับดูแล ซึ่งกระทบต่อการดำเนินงานของบริษัท แต่สามารถดำเนินการแก้ไขได้ในทันที | F19: ขัดต่อกฎหมาย/ข้อบังคับ กฏระเบียบของหน่วยงานภายนอกที่กำกับดูแล โดยได้รับบทลงโทษตามกฎหมาย หรือต้องแก้ไขตามคำสั่งของหน่วยงานภายนอกที่กำกับดูแล | G19: ขัดต่อกฎหมาย กฏระเบียบของหน่วยงานภายนอกที่กำกับดูแล โดยถูกเพิกถอนใบอนุญาต หรือถูกปิดกิจการ
C20: ระยะเวลาการดำเนินโครงการล่าช้า (ตั้งแต่ BOD Approval ถึง COD) | D20: < 3% จากแผนงาน หรือ < 1 เดือน | E20: 3% < X < 5% จากแผนงาน หรือ < 2 เดือน | F20: 5% < X < 10% จากแผนงาน หรือ < 3 เดือน | G20: ล่าช้าจากแผนงาน > 10% หรือ > 3 เดือน
C21: การกำกับดูแลบริษัทในเครือ | D21: การดำเนินงานเป็นไปตามนโยบาย/แนวทางของ GPSC และสามารถควบคุมได้ | E21: การดำเนินงานเป็นไปตามนโยบาย/แนวทางของ GPSC โดยไม่สามารถควบคุมได้ | F21: ไม่ดำเนินงานตามนโยบาย/แนวทางของ GPSC | G21: ไม่ดำเนินงานตามนโยบาย/แนวทางของ GPSC และส่งผลเสียหายต่อ GPSC
B22: ชื่อเสียงองค์กร (Image and Reputation) | C22: ภาพลักษณ์ GPSC ต่อสาธารณะ/สื่อ | D22: - | E22: ทำให้เกิดความไม่พอใจจากสาธารณะ เช่น การเขียนบทความวิจารณ์ | F22: ทำให้เกิดความไม่พอใจอย่างมากจากสาธารณะ เช่น การแสดงความเห็นคัดค้านผ่านสื่อต่างๆ | G22: ทำให้เกิดการต่อต้านอย่างรุนแรงจากสาธารณะ เช่น การประท้วงจากชุมชน
C23: ภาพลักษณ์ GPSC ต่อชุมชน | D23: มีผลกระทบต่อชุมชนรอบสถานประกอบการ/โรงงานเล็กน้อย โดยได้รับคำติเตียนข้อครหาอย่างไม่เป็นทางการผ่านช่องทางต่างๆ ของบริษัท | E23: มีผลกระทบต่อชุมชนรอบสถานประกอบการ/โรงงาน โดยได้รับข้อร้องเรียนอย่างเป็นลายลักษณ์อักษร และดำเนินแก้ไขได้ภายใน 1 สัปดาห์ | F23: มีผลกระทบต่อชุมชนรอบสถานประกอบการ/โรงงานโดย ได้รับข้อร้องเรียนอย่างเป็นลายลักษณ์อักษร และถูกดำเนินการตรวจสอบจากหน่วยงานกำกับดูแลจากภายนอก | G23: มีผลกระทบรุนแรงต่อชุมชนเป็นบริเวณกว้าง โดยได้รับคำสั่งหยุดการดำเนินการ หรือถูกประท้วงจากมวลชนจนไม่สามารถดำเนินธุรกิจได้
C24: สิ่งแวดล้อม | D24: เกิดผลกระทบต่อสิ่งแวดล้อมในบริเวณข้างเคียงเล็กน้อย โดยไม่ต้องมีมาตรการดำเนินการแก้ไข | E24: เกิดผลกระทบต่อสิ่งแวดล้อมโดยสามารถดำเนินการแก้ไขได้ภายใน 1 วัน หรือใช้ระยะเวลาในการบรรเทา/ฟื้นฟูให้กลับคืนสภาพได้ภายในระยะเวลา < 1 ปี | F24: เกิดผลกระทบต่อสิ่งแวดล้อมระดับรุนแรงโดยสามารถดำเนินการแก้ไขได้ในระยะเวลามากกว่า 1 วัน แต่ไม่เกิน 1 เดือน หรือสามารถใช้ระยะเวลาในการบรรเทา/ฟื้นฟูให้กลับคืนสภาพได้ภายในระยะเวลาตั้งแต่ 1-5 ปี | G24: เกิดผลกระทบต่อสิ่งแวดล้อมระดับรุนแรงมาก โดยสามารถดำเนินการแก้ไขได้ในระยะเวลามากกว่า 1 เดือน หรือต้องอาศัยระยะเวลามากกว่า 5 ปีขึ้นไปในการบรรเทา/ฟื้นฟู หรือเสียหายจนยากต่อการฟื้นฟู
B25: ด้านลูกค้า (Customers) | C25: ปริมาณขายผลิตภัณฑ์/บริการของ GPSC | D25: ลูกค้าที่ไม่ใช่ลูกค้าหลักลดการซื้อผลิตภัณฑ์/บริการ | E25: ลูกค้าที่ไม่ใช่ลูกค้าหลักเลิกซื้อผลิตภัณฑ์/บริการ | F25: ลูกค้าหลักลดการซื้อผลิตภัณฑ์/บริการ | G25: ลูกค้าหลักเลิกซื้อผลิตภัณฑ์/บริการ
C26: ความพึงพอใจของลูกค้า/คู่ค้า | D26: - | E26: ลูกค้า/คู่ค้าแสดงความไม่พอใจร้องเรียนกลับมาที่บริษัท | F26: ลูกค้า/คู่ค้าแสดงความไม่พอใจผ่านสื่อต่างๆ | G26: ลูกค้า/คู่ค้าฟ้องร้องบริษัท
B27: ด้านบุคคล (People) | C27: ความปลอดภัยและสุขภาพ | D27: พนักงาน ลูกค้า คู่ค้า หรือผู้มีส่วนได้ส่วนเสียได้รับบาดเจ็บจนต้องได้รับการปฐมพยาบาลทางการแพทย์ | E27: พนักงาน ลูกค้า คู่ค้า หรือผู้มีส่วนได้ส่วนเสีย ได้รับบาดเจ็บหรือเจ็บป่วยจนต้องได้รับการรักษาจากแพทย์ (OPD) แต่ไม่ต้องเข้าพักรักษาในโรงพยาบาล | F27: พนักงาน ลูกค้า คู่ค้า หรือผู้มีส่วนได้ส่วนเสีย ได้รับบาดเจ็บหนักหรือเจ็บป่วยจนต้องเข้าพักรักษาในโรงพยาบาล (IPD) | G27: พนักงาน ลูกค้า คู่ค้า หรือผู้มีส่วนได้ส่วนเสีย ทุพพลภาพ/เสียชีวิต
C28: ความพึงพอใจของพนักงาน | D28: พนักงานเกิดความไม่พอใจ และสามารถบริหารจัดการแก้ไขได้ภายในหน่วยงาน | E28: พนักงานเกิดความไม่พึงพอใจ และมีความจำเป็นต้องอาศัยหน่วยงานกลาง (HR) ในการดำเนินการแก้ไข | F28: พนักงานเกิดความไม่พึงพอใจสูง และมีการร้องเรียนผ่านช่องทางภายในบริษัท | G28: พนักงานเกิดความไม่พึงพอใจรุนแรง เช่น นัดหยุดงานหรือลาออก และส่งผลให้การดำเนินธุรกิจหยุดชะงัก หรือเกิดข้อพิพาทที่ต้องเข้าสู่กระบวนการทางกฎหมาย

Sheet Risk Criteria (ENG)
B1: GPSC Risk Criteria
G2: (Version as of 7 Aug 2019)
B3: Likelihood | D3: Level
D4: Low 1 | E4: Medium 2 | F4: High 3 | G4: Extreme 4
B6: Likelihood | D6: < 10% | E6: >10% to < 20% | F6: >20% to < 50% | G6: > 50%
D7: Never or occure 1 time in 5 years | E7: Occure 1 time in 3 years | F7: Occure 1 time in a year | G7: Occure more than 1 time in a year
B9: Impact | D9: Level
D10: Low 1 | E10: Medium 2 | F10: High 3 | G10: Extreme 4
B12: Financial | C12: Net Profit: Lower than Target | D12: < 1.25% | E12: > 1.25% to < 2.5% | F12: > 2.5% to < 5% | G12: > 5%
C13: EBITDA: Lower than Target | D13: < 1.25% | E13: > 1.25% to < 2.5% | F13: > 2.5% to < 5% | G13: > 5%
C14: Revenue: Lower than Target | D14: < 1.25% | E14: > 1.25% to < 2.5% | F14: > 2.5% to < 5% | G14: > 5%
C15: Expense: Higher than Target | D15: < 1.25% | E15: > 1.25% to < 2.5% | F15: > 2.5% to < 5% | G15: > 5%
C16: Project Return: Equity IRR Lower than Target | D16: < 5 % from base case | E16: > 5 % to < 10 % from base case | F16: > 10% to < 15% from base case | G16: >15 % to base case
C17: Project Cost Overrun | D17: < 1.25% from base case | E17: > 1.25% to < 2.5% from base case | F17: > 2.5% to < 5% from base case | G17: > 5% from base case
B18: Business Process and Operation | C18: Process Effectiveness | D18: Slight/Minor impact on operating/core process, and can be controlled and recovered by owner | E18: Moderate impact on operating/core process, and need support from related party to control and recover | F18: High impact on operating/core process, and need to stop/slow down some part of the core process | G18: Extreme impact on operating/core process, and also affect to customers' product or business target
C19: Product/Service | D19: Delay in delivery of the product/service | E19: Delay in delivery and unable to meet quality standard of the product/service | F19: Delivery of the product/service cannot be done | G19: Delivery of the product/service cannot be done, and company is charged with additional costs or damage claim
C20: Regulatory Compliance | D20: Not comply with the regulations, policies, procedures and standards of the company | E20: Not comply with the laws and regulations from external regulator, but can be resolved immediately | F20: Not comply with the laws and regulations from external regulator, and be punished according to law or required to remedy according to external regulator's order | G20: Not comply with the laws and regulations from external regulator, and cause revokation of license or dissolution
C21: Project Delay (from BOD Approval Plan) | D21: < 3% from plan or < 1 month | E21: 3% < X < 5% from plan or < 2 months | F21: 5% < X < 10% from plan or < 3 months | G21: Delay from plan > 10% or > 3 months
C22: Subsidiary Management | D22: Managing subsidiary aligns with GPSC's policy or GPSC way of conduct, and can be controlled | E22: Managing subsidiary aligns with GPSC's policy or GPSC way of conduct, and cannot be controlled | F22: Managing subsidiary does not align with GPSC's policy or GPSC way of conduct | G22: Managing subsidiary does not align with GPSC's policy or GPSC way of conduct, and caues impact to GPSC business
B23: Image and Reputation | C23: GPSC Image to Public/Media | D23: - | E23: Moderate adveres impact from the public i.e. negative criticism in publication | F23: High adveres impact from the public i.e. negative feedback in media coverage | G23: Extreme adveres impact from the public i.e. local community protest
C24: GPSC Image to Community | D24: Minor impact on local community with informal feedback from various internal company channels | E24: Impact on local community with formal letter, but can be recovered within 1 week | F24: Impact on local community with formal letter, and be investigated from external regulator | G24: Extreme impact on community in wide area, and be ordered to stop operation or unable to operate due to the protest
C25: Environment | D25: Minor impact on the environment in surrounding areas without required additional action | E25: Impact on the environment which can be resolved within 1 day or need less than 1 week for restoration/rehabilitation | F25: High impact on the environment which can be resolved withinh 1 month or need 1-5 years for restoration/rehabilitation | G25: Extreme impact on the environment which can be resolved more than 1 month or need more than 5 years for restoration/rehabilitation
B26: Customers | C26: Volume of Product/Service | D26: General customer reduces purchasing of products/services. | E26: General customer stops purchasing of products/services. | F26: Main customer reduces purchasing of products/services. | G26: Main customer stops purchasing of products/services.
C27: Customer/Partner Satisfaction | D27: - | E27: Complaint of dissatisfacton from customer/partner is reported to the company | F27: Dissatisfaction from customer/partner is published in media channels | G27: Customer/partner sues the company
B28: People | C28: Health and Safety | D28: Employee, customer, partner, or stakeholder is injured and required medical first aid | E28: Employee, customer, partner, or stakeholder is injured and required medical treatment (OPD) | F28: Employee, customer, partner, or stakeholder is severely injured and required hospitalization (IPD). | G28: Employee, customer, partner, or stakeholder is permanent incapacity/dealth
C29: Employee Engagement | D29: Employees are dissatisfied, and the issues can be managed within the department | E29: Employees are dissatisfied, and need HR department to resolve the issues | F29: Employees are severely dissatisfied, and complaints are addressed through company channels | G29: Employees are extremely dissatisfied and expressed by resigning or protesting, which result in business interruption or legal dispute

Sheet Data1
A2: พื้นที่
A3: GPSC BKK : EnCo B - 5th floor
A4: GPSC BKK : EnCo B - 18th floor
A5: GPSC BKK : Empire Tower
A6: GPSC CBI : GIPP
A7: GPSC CBI : IPP1
A8: GPSC RYG : Central Warehouse
A9: GPSC RYG : CUP-1
A10: GPSC RYG : CUP-2
A11: GPSC RYG : CUP-3
A12: GPSC RYG : CUP-4
A13: GPSC RYG : Energy Storage Factory
... A18: GPSC RYG : SPP2/3
A21: BFS | B21: โครงการแฟลซ
A22: ESS | B22: ฝ่ายกลยุทธ์ซ่อมบำรุงโรงไฟฟ้า
A23: SCS | B23: ฝ่ายกลยุทธ์องค์กรและบริหารความเสี่ยง
A24: FFS | B24: ฝ่ายการเงินองค์กร
A25: CGS | B25: ฝ่ายการพาณิชย์ กลุ่มลูกค้า GPSCและบริหารสัญญา
A26: HES | B26: ฝ่ายความมั่นคงปลอดภัย อาชีวอนามัและสิ่งแวดล้อม
A27: PSS | B27: ฝ่ายจัดซื้อ
A28: EMS | B28: ฝ่ายซ่อมบำรุงโรงไฟฟ้า
A29: IAS | B29: ฝ่ายตรวจสอบภายในองค์กร
A30: BNS | B30: ฝ่ายนวัฒกรรมและเทคโนโลยีพลังงาน
A31: STS | B31: ฝ่ายบริหารการเปลี่ยนแปลงและความยั่งยืนองค์กร
A32: JCS | B32: ฝ่ายบริหารโครงการก่อสร้าง
... A63: CRV | B63: หน่วยลูกค้าสัมพันธ์ Glow
B66: 1 | C66: Financial
B67: 2 | C67: Strategy and Business Growth
B68: 3 | C68: Subsidiary Management
B69: 4 | C69: Operational Management
B70: 5 | C70: Quality, Safety, Health, and Environment
B71: 6 | C71: Human Resource and Organization Capability
B72: 7 | C72: Project Execution
B73: 8 | C73: Legal, Regulation and Compliance
A76: A. สูญเสียรายได้โดยตรง | C76: F - กำไรสุทธิต่ำกว่าเป้าหมาย
A77: B.ผลกระทบต่อลูกค้า | C77: F - กำไรขั้นต้นต่ำกว่าเป้าหมาย | E77: Likelyhood Level | F77: Impact Level
A78: C.ผลกระทบต่อชีวิตและความปลอดภัย | C78: F - รายได้ต่ำกว่าเป้าหมาย | E78: - | F78: -
A79: D.การหยุดชะงักของการปฏิบัติงาน/หน้าที่และงานประจำวัน | C79: F - ค่าใช้จ่ายสูงกว่าเป้าหมาย | E79: 1 | F79: 1
A80: E.ผลกระทบต่อชื่อเสียง | C80: F - ผลตอบแทนการลงทุนต่ำกว่าเป้าหมาย | E80: 2 | F80: 2
A81: F.ผลกระทบต่อสัญญา/ข้อตกลงระดับของการให้บริการ | C81: F - ประมาณลงทุนสูงกว่าที่ได้รับอนุมัติ | E81: 3 | F81: 3
...

Sheet 2. BIA Process
A1: Process กระบวนการผลิต | B1: Impact Category ประเภทของผลกระทบที่เกิดขึ้น | C1: 1 Hour | D1: 4 Hour | E1: 8 Hour | F1: 12 Hour | G1: 24 Hour | H1: 3 Days | I1: 14 Days | J1: 30 Days | K1: Severity overtime scores | L1: Maximum Tolerable Period of Disruption (MTPD) | M1: Recovery Time Objective (RTO) | N1: Minimum Business Continuity Objective (MBCO) | O1: Posible Risk ความเสี่ยงที่เป็นไปได้ | P1: Existing Control มาตรการควบคุมที่มีอยู่ | Q1: Mitigation Plan (new countermeasure to reduce threats) | R1: Possible Risk Scores | S1: Existing Control Scores | T1: Mitigation Scores | U1: Prevention scores
A2: การรับวัตถุดิบ (น้ำDemin) | B2: การเงิน | C2: 1 | D2: 1 | E2: 1 | F2: 1 | G2: 2 | H2: 2 | I2: 3 | J2: 4 | K2: =SUM(C2*8)+(D2*7)+(E2*6)+(F2*5)+(G2*4)+(H2*3)+(I2*2)+(J2*1) -> 50 | L2: 24 Hours | M2: 1 Hours | N2: 1 | O2: 1.ถังกักเก็บน้ำชำรุดรั่วไหล 2.ท่อส่งเข้าระบบเสียหาย 3.อุปกรณ์ควบคุมใช้งานไม่ได้ | P2: 1.1จัดหาแหล่งน้ำสำรองจากแหล่งอื่นๆ เช่น WHA 1.2 จัดหาแหล่งน้ำสำรองจากแหล่งอื่นๆ เช่นเชื่อมระบบกับ Glow & CUP3 2.1มีการตรวจสอบ รายวัน 2.2มีทีมซ่อมบำรุง on call 24 hr 3.1มีการกำหนดแผนซ่อมบำรุงตามระยะเวลากำหนด 3.2มีสัญญาเข้าซ่อมบำรุงระบบ | R2: 6 | S2: 3 | T2: 0 | U2: =(S2+T2)/(R2*100) -> 0.005
A3: 2.การรับวัตถุดิบ (น้ำ Clearify water) | B3: การเงิน | C3: 1 | D3: 1 | E3: 1 | F3: 1 | G3: 2 | H3: 2 | I3: 2 | J3: 2 | K3: =SUM(C3*8)+(D3*7)+(E3*6)+(F3*5)+(G3*4)+(H3*3)+(I3*2)+(J3*1) -> 46 | L3: 24 Hours | M3: 1 Hours | N3: 1 | O3: 1.ถังกักเก็บน้ำชำรุดรั่วไหล 2.ท่อส่งเข้าระบบเสียหาย 3.อุปกรณ์ควบคุมใช้งานไม่ได้ | P3: 1.1จัดหาแหล่งน้ำxxx 2.1มีการตรวจสอบ รายวัน 2.2มีทีมซ่อมบำรุง on call 24 hr 3.1มีการกำหนดแผนซ่อมบำรุงตามระยะเวลากำหนด 3.2มีสัญญาเข้าซ่อมบำรุงระบบ | Q3: 1.ปรับลดปริมาณการใช้น้ำในกระบวนการผลิต 2.พิจารณาหาแหล่งน้ำสำรอง เช่น รถขนส่งน้ำจากภายนอก 3.หาแหล่งน้ำดิบเพิ่มอีกแหล่ง เช่น จากบริษัท EAST WATER | R3: 3 | S3: 5 | T3: 3 | U3: =(S3+T3)/(R3*100) -> 0.026666667
A4: 3.การรับวัตถุดิบ (สารเคมี) | B4: การเงิน | C4: 1 | D4: 1 | E4: 1 | F4: 1 | G4: 2 | H4: 2 | I4: 3 | J4: 4 | K4: =SUM(C4*8)+(D4*7)+(E4*6)+(F4*5)+(G4*4)+(H4*3)+(I4*2)+(J4*1) -> 50 | L4: 24 Hours | M4: 1 Hours | N4: 1 | O4: 1.ปริมาณสารเคมีไม่พอใช้งาน 2.ถังกักเก็บสารเคมีชำรุดรั่วไหล | P4: 1.1มี On call ผู้จำหน่ายสารเคมี (12 ชม.) 1.2มีการควบคุมปริมาณขั้นต่ำ (Max-Min) สารเคมี 2.1มีกำหนดการตรวจสอบและซ่อมบำรุงถังxxxxx | Q4: 1.จัดหาให้มีระบบถังสารเคมีสำรองเพิ่มอีก 1 ถัง ในการใช้งาน | R4: 2 | S4: 3 | T4: 1 | U4: =(S4+T4)/(R4*100) -> 0.02
A5: 4.การรับวัตถุดิบ (ก๊าซเชื้อเพลิง) | B5: การเงิน | C5: 1 | D5: 1 | E5: 1 | F5: 1 | G5: 2 | H5: 3 | I5: 4 | J5: 4 | K5: =SUM(C5*8)+(D5*7)+(E5*6)+(F5*5)+(G5*4)+(H5*3)+(I5*2)+(J5*1) -> 55 | L5: 48 Hours | M5: 1 Hours | N5: 1 | O5: 1.ไม่มีก๊าซหรือก๊าซไม่เพียงพอ 2.ท่อส่งเข้าระบบเสียหาย, อุปกรณ์ควบคุมใช้งานไม่ได้ 3.ไฟไหม้ | P5: 1.1มีการตรวจสอบ รายวัน 1.2มีทีมซ่อมบำรุง on call 24 hr 2.1มีการกำหนดแผนซ่อมบำรุงตามระยะเวลากำหนด 2.2มีสัญญาเข้าซ่อมบำรุงระบบ 3.1มีระบบดับเพลิงเครื่องจักร 2 ตัวเพื่อช่วยในการดับเพลิง | Q5: 1.ทำระบบไฟฟ้าส่งจ่ายจาก GLOW,PEA มาจ่ายให้กับลูกค้าแทน 2.ทำระบบท่อไอน้ำจาก GLOW มาจ่ายให้กับลูกค้า | R5: 3 | S5: 5 | T5: 2 | U5: =(S5+T5)/(R5*100) -> 0.023333333
A6: 5.การรับวัตถุดิบ (น้ำมันเชื้อเพลิงสำหรับระบบดับเพลิง) | B6: การเงิน | C6: 1 | D6: 1 | E6: 1 | F6: 1 | G6: 1 | H6: 1 | I6: 1 | J6: 1 | K6: =SUM(C6*8)+(D6*7)+(E6*6)+(F6*5)+(G6*4)+(H6*3)+(I6*2)+(J6*1) -> 36 | L6: 48 Hours | M6: 1 Hours | N6: 1 | O6: 1.ปริมาณน้ำมันเชื้อเพลิงไม่พอใช้งาน | P6: 1.มีระบบดับเพลิงเครื่องจักร 2 ตัวเพื่อช่วยในการดับเพลิง 2.มีการซ้อมแผนฉุกเฉินเป็นประจำทุกๆปี 3.มีการตรวจสอบอุปกรณ์เครื่องจักรตามแผนงานซ่อมบำรุงประจำปี | Q6: 1.จัดหาให้มีระบบน้ำมันเชื้อเพลิงสำรองเพิ่ม ในการใช้งาน 2.ติดต่อหน่วยงานที่เกี่ยวข้องเพื่อจัดเตรียมรถดับเพลิงในกรณีฉุกเฉิน (NPCS&E) | R6: 1 | S6: 3 | T6: 2 | U6: =(S6+T6)/(R6*100) -> 0.05
A7: 6.การรับวัตถุดิบ (ไฟฟ้าสำหรับ Start up process) | B7: การเงิน | C7: 1 | D7: 1 | E7: 1 | F7: 1 | G7: 2 | H7: 2 | I7: 3 | J7: 3 | K7: =SUM(C7*8)+(D7*7)+(E7*6)+(F7*5)+(G7*4)+(H7*3)+(I7*2)+(J7*1) -> 49 | L7: 24 Hours | M7: 1 Hours | N7: 1 | O7: 1.การผลิตหยุดชะงักเนื่องจากไม่มีกระแสไฟฟ้า 2.ไม่สามารถ Start กระบวนการผลิตได้กรณีที่สายส่ง EGAT/ PEA ชำรุดส่งผลให้ Plant Blackout | P7: 1.1มีสัญญาการรับไฟฟ้าจากการไฟฟ้า 2.1จัดทำแผนซ่อมบำรุง อุปกรณ์ตามระยะเวลาที่กำหนด 2.2มีทีม on call ซ่อมบำรุง 24 ชม. | Q7: 1.ศึกษาการจัดหาแหล่งไฟฟ้าสำรองในการ Start plant จากแหล่งอื่น เช่น Diesel GEN. 2.ศึกษาการเชื่อมต่อระบบกับ Glow ในการ Charge Back | R7: 2 | S7: 3 | T7: 2 | U7: =(S7+T7)/(R7*100) -> 0.025
A8: 7.เดินเครื่องระบบ BOP (Cooling, Air Compressor ) | B8: การเงิน | C8: 1 | D8: 1 | E8: 1 | F8: 1 | G8: 2 | H8: 2 | I8: 3 | J8: 3 | K8: =SUM(C8*8)+(D8*7)+(E8*6)+(F8*5)+(G8*4)+(H8*3)+(I8*2)+(J8*1) -> 49 | L8: 7 Days | M8: 7 Days | N8: 1 | O8: 1. การผลิตหยุดเนื่องจากไม่มีกระแสไฟฟ้า 2.การผลิตหยุดเนื่องจากไม่มีน้ำ | P8: 1.1มีระบบ อัตโนมัติควบคุม 2 ตัวขึ้นไปในการใช้งานกระบวนการผลิต 1.2มีระบบ by pass 1.3มีระบบควบคุมอัตโนมัติ (Emergency) และระบบป้องกันอุปกรณ์(Protection)) เพื่อป้องกันเครื่องจักรเสียหาย 1.4มีการติดตั้งอุปกรณ์สำรอง 1.5มีแผนซ่อมบำรุงรักษาประจำปี/ ประจำเดือน 2.1มีการจด log sheet เพื่อประเมินค่าของอุปกรณ์ว่าผิดปกติหรือไม่และ Visual check ขณะทำการจด log sheet | Q8: 1.สำรองติดตั้ง Mobile Air compressor ชั่วคราวโดยทำสัญญากับ Supplier | R8: 2 | S8: 6 | T8: 1 | U8: =(S8+T8)/(R8*100) -> 0.035
A9: 8.เดินเครื่องระบบ Fuel Gas | B9: การเงิน | C9: 1 | D9: 1 | E9: 1 | F9: 1 | G9: 2 | H9: 2 | I9: 3 | J9: 3 | K9: =SUM(C9*8)+(D9*7)+(E9*6)+(F9*5)+(G9*4)+(H9*3)+(I9*2)+(J9*1) -> 49 | L9: 7 Days | M9: 7 Days | N9: 1 | O9: 1.ไม่สามารถเดินเครื่องได้เนื่องจากไม่มีก๊าซทำให้ระบบเครื่องจักรการผลิตหยุดชะงัก | P9: 1.1 มีแผนซ่อมบำรุงรักษาประจำปี/ ประจำเดือน 1.2 มีการติดตั้งอุปกรณ์สำรอง 1.3 มีการจด log sheet เพื่อประเมินค่าของอุปกรณ์ว่าผิดปกติหรือไม่และ Visual check ขณะทำการจด log sheet | Q9: 1.ให้มีทีมซ่อมบำรุง และชิ้นส่วนอะไหล่ ตลอด24 ชม. เพื่อไม่ต้องเสียเวลาในการรอคอย ในขณะที่ตาม oncall | R9: 1 | S9: 3 | T9: 1 | U9: =(S9+T9)/(R9*100) -> 0.04
A10: 9.เดินเครื่องระบบ Demin, Condensate และ Neutralization. | B10: การเงิน | C10: 1 | D10: 1 | E10: 1 | F10: 1 | G10: 2 | H10: 2 | I10: 3 | J10: 3 | K10: =SUM(C10*8)+(D10*7)+(E10*6)+(F10*5)+(G10*4)+(H10*3)+(I10*2)+(J10*1) -> 49 | L10: 7 Days | M10: 7 Days | N10: 1 | O10: 1.ไม่สามารถผลิตน้ำ Demin ได้เนื่องจากไม่มีกระแสไฟฟ้า 2.ปริมาณน้ำ Demin ไม่เพียงพอต่อการใช้งานในการบวนการผลิตและส่งให้ลูกค้าได้ | P10: 1.1มีการติดตั้งระบบสำรองในการผลิตนำ Demin 4 units, Condensate 2 units. 1.2ระบบ Pump Neutralization มี 2 unit สามารถได้สลับกันได้กรณีอีกตัวเสีย 2.1มีระบบนำ RO เพิ่มอีก 2 units ในกระบวนการผลิตเพื่อช่วยผลิตน้ำได้ 2.2รับน้ำ Demin จาก WHA | Q10: 1.พิจารณาหาแหล่งน้ำสำรอง เช่น รถขนส่ง 2.จัดหาแหล่งน้ำสำรองจากแหล่งอื่นๆ เช่น เชื่อมระบบกับ Glow & CUP3 | R10: 2 | S10: 4 | T10: 2 | U10: =(S10+T10)/(R10*100) -> 0.03
A11: 10.เดินเครื่องระบบ BFW และ Deaerator | B11: การเงิน | C11: 1 | D11: 1 | E11: 1 | F11: 1 | G11: 2 | H11: 2 | I11: 3 | J11: 3 | K11: =SUM(C11*8)+(D11*7)+(E11*6)+(F11*5)+(G11*4)+(H11*3)+(I11*2)+(J11*1) -> 49 | L11: 7 Days | M11: 7 Days | N11: 1 | O11: 1. ไม่สามารถเดินระบบได้เนื่องจากไม่มีกระแสไฟฟ้า 2.การผลิตหยุดเนื่องจากไม่มีน้ำ | P11: 1.1xxxxx 2.1xxxxx | Q11: 1.ให้มีทีมซ่อมบำรุง และชิ้นส่วนอะไหล่ ตลอด24 ชม. เพื่อไม่ต้องเสียเวลาในการรอคอย ในขณะที่ตาม oncall 2.หาแหล่งน้ำอื่นๆเช่น BFW จาก CUP3 ส่งให้ลูกค้าแทนได้ | R11: 2 | S11: 2 | T11: 2 | U11: =(S11+T11)/(R11*100) -> 0.02
A12: 11.เดินเครื่อง Aux Boiler , HRSG และ Emission Control. | B12: การเงิน | C12: 1 | D12: 1 | E12: 1 | F12: 1 | G12: 2 | H12: 2 | I12: 3 | J12: 3 | K12: =SUM(C12*8)+(D12*7)+(E12*6)+(F12*5)+(G12*4)+(H12*3)+(I12*2)+(J12*1) -> 49 | L12: 7 Days | M12: 7 Days | N12: 1 | O12: 1. การผลิตไอน้ำหยุดเนื่องจากไม่มีกระแสไฟฟ้า 2.การผลิตไอน้ำหยุดเนื่องจากไม่มีน้ำ 3.การผลิตไอน้ำหยุดเนื่องจากไม่มีเชื้อเพลิง 4.การผลิตไอน้ำหยุดเนื่องจากปริมาณสารเคมีไม่พอใช้งาน 5.ไม่สอดคล้องตามกฏหมาย ค่า Emission เกินมาตราฐาน เนื่องจากไม่มีสารเคมีใช้ในกระบวนการผลิต (No chemical) | P12: 1.1มีสัญญาการรับไฟฟ้าจากการไฟฟ้า 2.1xxxx 3.1xxxxx 4.1มี On call ผู้จำหน่ายสารเคมี (12 ชม.) 4.2มีการควบคุมปริมาณขั้นต่ำ (Max-Min) สารเคมี 5.1 มีระบบควบคุม Emission และระบบเตือนเมื่อค่าเกิดค่าที่ควบคุม | Q12: 1.ให้มีทีมซ่อมบำรุง และชิ้นส่วนอะไหล่ ตลอด24 ชม. เพื่อไม่ต้องเสียเวลาในการรอคอย ในขณะที่ตาม oncall 2.หาแหล่งไอน้ำอื่นๆ เช่น รับจาก CUP3,CUP4&GLOW ส่งให้ลูกค้าแทนได้ | R12: 5 | S12: 5 | T12: 2 | U12: =(S12+T12)/(R12*100) -> 0.014
A13: 12.เดินเครื่องระบบ GTG | B13: การเงิน | C13: 1 | D13: 1 | E13: 1 | F13: 1 | G13: 2 | H13: 2 | I13: 3 | J13: 3 | K13: =SUM(C13*8)+(D13*7)+(E13*6)+(F13*5)+(G13*4)+(H13*3)+(I13*2)+(J13*1) -> 49 | L13: 140 Days | M13: 140 Days | N13: 1 | O13: 1. การผลิตไฟฟ้าหยุดเนื่องจากไม่มีกระแสไฟฟ้า 2.การผลิตไฟฟ้าหยุดเนื่องจากไม่มีก๊าซ หรือก๊าซไม่เพียงพอ 3.ไฟไหม้ | P13: 1.1xxx 2.1xxx 3.1มีระบบควบคุมอัตโนมัติ (Emergency) และระบบป้องกันอุปกรณ์(Protection)) เพื่อป้องกันเครื่องจักรเสียหาย 3.2มีการจัดทำแผนตอบโต้ฉุกเฉิน ตาม Mitigation plan ภายในการเดินเครื่อง 3.3มีแผนซ่อมบำรุงรักษาประจำปี/ ประจำเดือน 3.4มีแผนการตรวจสอบระบบเครื่องจักร ตามระยะเวลาที่กำหนด | Q13: 1.ให้มีทีมซ่อมบำรุง และชิ้นส่วนอะไหล่ ตลอด24 ชม. เพื่อไม่ต้องเสียเวลาในการรอคอย ในขณะที่ตาม oncall 2.หาแหล่งไฟฟ้าอื่นๆ เช่น รับจาก PEA,CUP4&GLOW ส่งให้ลูกค้าแทนได้ | R13: 3 | S13: 4 | T13: 2 | U13: =(S13+T13)/(R13*100) -> 0.02
A14: 13.เดินเครื่องระบบส่งผ่านผลิตภัณฑ์ (สายไฟฟ้า) | B14: การเงิน | C14: 1 | D14: 1 | E14: 1 | F14: 1 | G14: 2 | H14: 2 | I14: 3 | J14: 3 | K14: =SUM(C14*8)+(D14*7)+(E14*6)+(F14*5)+(G14*4)+(H14*3)+(I14*2)+(J14*1) -> 49 | L14: 7 Days | M14: 7 Days | N14: 1 | O14: 1.ไม่มีกระแสไฟฟ้า 2.สายส่งไฟฟ้าชำรุดจึงไม่สามารถส่งกระแสไฟฟ้าให้กับลูกค้าได้ | P14: 1.1xxx 2.1มีการตรวจสอบอุปกรณ์ป้องกัน โดยพนักงานเดินเครื่อง และสายส่งโดยทีมงานซ่อมบำรุง อย่างประจำ 2.2มีแผนการซ่อมบำรุงรักษาระบบส่งจ่ายไฟฟ้ารายปี มีแผนการตรวจสอบระบบส่งจ่ายไฟฟ้าตามระยะเวลาที่กำหนด 2.3มีทีมปฏิบัติการในกรณีฉุกเฉิน (on-call) ตลอด 24 ชม. สำหรับงานซ่อมเร่งด่วน 2.4จัดเตรียมสายไฟฟ้าสำรองไว้เปลี่ยนในกรณีเกิดเหตุฉุกเฉิน 2.5 มีระบบควบคุมอัตโนมัติ (Emergency) และระบบป้องกันอุปกรณ์(Protection) เพื่อป้องกันเครื่องจักรเสียหาย | Q14: 1.เพิ่มระบบสายส่งเป็น 2 Feeder ใช้งาน 1 Feeder Standby เตรียมพร้อมอีก 1 Feeder (EGAT) 2.สลับแหล่งจ่ายไฟลูกค้า GPSC ไปรับยัง บริษัท Glow | R14: 2 | S14: 6 | T14: 2 | U14: =(S14+T14)/(R14*100) -> 0.04
... A20: 19.ระบบควบคุมการผลิต ( UPS ,DCS) | B20: การเงิน | C20: 1 | D20: 1 | E20: 1 | F20: 1 | G20: 2 | H20: 2 | I20: 3 | J20: 3 | K20: =SUM(C20*8)+(D20*7)+(E20*6)+(F20*5)+(G20*4)+(H20*3)+(I20*2)+(J20*1) -> 49 | L20: 60 Days | M20: 60 Days | N20: 1 | O20: 1.ไม่มีกระแสไฟฟ้าจ่ายเข้าระบบ 2.ระบบ UPS failedและ หรือ ระบบ DCS failed | P20: 1.1มีระบบควบคุมเป็นแบบ ขนาน 2 ระบบ 2.1มีการตรวจสอบ PM ระบบ 2.2ในกรณีที่ระบบ failed จะมีการแจ้งเตือนและระบบ สำรองจะเข้ามาควบคุมแทน 2.3มี manual valve ที่หน้างาน 2.4มีby pass control valve ที่หน้างาน 2.5มีชำนาญการระบบ DCS vender oncall 24ชม. | Q20: 1.ให้มีทีมซ่อมบำรุงชำนาญเฉพาะทาง ประสานงานกับทาง Vender และมีการเตรียมชิ้นส่วนอะไหล่ ตลอด24 ชม. เพื่อใช้งานและไม่ต้องเสียเวลาในการรอคอย ในขณะที่ตาม oncall 2.ให้มีทีมซ่อมสายส่งของ Vender (Contactor)ตลอด24ชม. | R20: 2 | S20: 6 | T20: 2 | U20: =(S20+T20)/(R20*100) -> 0.04

Sheet 3.RA Process
A1: No. | B1: Product & Service ผลิตภัณฑ์และบริการ | C1: Process กระบวนการผลิต | D1: Risk Category ประเภทความเสี่ยง | E1: Impact Type ประเภทผลกระทบ | F1: Sub-Dimension | G1: Posible Risk ความเสี่ยงที่เป็นไปได้ | H1: Existing Control มาตรการควบคุมที่มีอยู่ | I1: Risk Assessment | P1: Mitigation Plan (new countermeasure to reduce threats) | Q1: Time Frame | S1: Responsible Person | T1: Target
I2: I | J2: L | K2: R | L2: R | M2: MTPD | N2: RTO | O2: MBCO | Q2: From | R2: To | T2: I | U2: L | V2: R | W2: R
A3: 1 | B3: 1.การผลิตไฟฟ้า | C3: การรับวัตถุดิบ (น้ำDemin) | D3: Operational Management | E3: 6.กระบวนการทางธุรกิจและการปฏิบัติการ | F3: ประสิทธิผลของกระบวนการ | G3: 1.ถังกักเก็บน้ำชำรุดรั่วไหล | H3: 1.1จัดหาแหล่งน้ำสำรองจากแหล่งอื่นๆ เช่น WHA 1.2 จัดหาแหล่งน้ำสำรองจากแหล่งอื่นๆ เช่นเชื่อมระบบกับ Glow & CUP3 | I3: 4 | J3: 1 | K3: =L3 -> E4 | L3: =IF(AND(J3=1,I3=1),"L16",IF(AND(J3=1,I3=2),"L14",IF(AND(J3=1,I3=3),"M11",IF(AND(J3=1,I3=4),"E4",IF(AND(J3=2,I3=1),"L15",IF(AND(J3=2,I3=2),"M12",IF(AND(J3=2,I3=3),"H7",IF(AND(J3=2,I3=4),"E3",IF(AND(J3=3,I3=1),"M13",IF(AND(J3=3,I3=2),"H9",IF(AND(J3=3,I3=3),"E6",IF(AND(J3=4,I3=4),"E2",IF(AND(J3=4,I3=1),"H10",IF(AND(I3=2,J3=4),"H8",IF(AND(J3=4,I3=3),"E5",IF(AND(J3=4,I3=4),"E1",FALSE)))))))))))))))) -> E4 | M3: ='2.2 BIA Process'!N8 -> 24 ชม | N3: ='2.2 BIA Process'!O8 -> 1 ชม | O3: ='2.2 BIA Process'!P8 -> 1 | P3: - | Q3: - | R3: - | S3: - | T3: 4 | U3: 1 | V3: =W3 -> E4 | W3: =IF(AND(U3=1,T3=1),"L16",IF(AND(U3=1,T3=2),"L14",IF(AND(U3=1,T3=3),"M11",IF(AND(U3=1,T3=4),"E4",IF(AND(U3=2,T3=1),"L15",IF(AND(U3=2,T3=2),"M12",IF(AND(U3=2,T3=3),"H7",IF(AND(U3=2,T3=4),"E3",IF(AND(U3=3,T3=1),"M13",IF(AND(U3=3,T3=2),"H9",IF(AND(U3=3,T3=3),"E6",IF(AND(U3=4,T3=4),"E2",IF(AND(U3=4,T3=1),"H10",IF(AND(U3=2,T3=4),"H8",IF(AND(U3=4,T3=3),"E5",IF(AND(U3=4,T3=4),"E1",FALSE)))))))))))))))) -> E4
F4: ประสิทธิผลของกระบวนการ | G4: 2.ท่อส่งเข้าระบบเสียหาย | H4: 2.1 มีการตรวจสอบ รายวัน 2.2มีทีมซ่อมบำรุง on call 24 hr | I4: 4 | J4: 1 | K4: =L3 -> E4
F5: ผลิตภัณฑ์หรือ บริการ | G5: 3.อุปกรณ์ควบคุมใช้งานไม่ได้ | H5: 3.1มีการกำหนดแผนซ่อมบำรุงตามระยะเวลากำหนด 3.2มีสัญญาเข้าซ่อมบำรุงระบบ | I5: 3 | J5: 1 | K5: =L7 -> M11
A6: 2 | B6: 1.การผลิตไฟฟ้า | C6: การรับวัตถุดิบ (น้ำ Clearify water) | D6: Operational Management | E6: 6.กระบวนการทางธุรกิจและการปฏิบัติการ | G6: 1.ถังกักเก็บน้ำชำรุดรั่วไหล 2.ท่อส่งเข้าระบบเสียหาย 3.อุปกรณ์ควบคุมใช้งานไม่ได้ | H6: 1.1จัดหาแหล่งน้ำxxx 2.1มีการตรวจสอบ รายวัน 2.2มีทีมซ่อมบำรุง on call 24 hr 3.1มีการกำหนดแผนซ่อมบำรุงตามระยะเวลากำหนด 3.2มีสัญญาเข้าซ่อมบำรุงระบบ | I6: 4 | J6: 1 | K6: =L6 -> E4 | L6: =IF(AND(J6=1,I6=1),"L16",IF(AND(J6=1,I6=2),"L14",IF(AND(J6=1,I6=3),"M11",IF(AND(J6=1,I6=4),"E4",IF(AND(J6=2,I6=1),"L15",IF(AND(J6=2,I6=2),"M12",IF(AND(J6=2,I6=3),"H7",IF(AND(J6=2,I6=4),"E3",IF(AND(J6=3,I6=1),"M13",IF(AND(J6=3,I6=2),"H9",IF(AND(J6=3,I6=3),"E6",IF(AND(J6=4,I6=4),"E2",IF(AND(J6=4,I6=1),"H10",IF(AND(I6=2,J6=4),"H8",IF(AND(J6=4,I6=3),"E5",IF(AND(J6=4,I6=4),"E1",FALSE)))))))))))))))) -> E4 | M6: ='2.2 BIA Process'!N9 -> 24 ชม | N6: ='2.2 BIA Process'!O9 -> 1 ชม | O6: ='2.2 BIA Process'!P9 -> 1 | P6: 1.ปรับลดปริมาณการใช้น้ำในกระบวนการผลิต 2.พิจารณาหาแหล่งน้ำสำรอง เช่น รถขนส่งน้ำจากภายนอก 3.หาแหล่งน้ำดิบเพิ่มอีกแหล่ง เช่น จากบริษัท EAST WATER | Q6: Jan | R6: Dec | S6: Operation | T6: 3 | U6: 1 | V6: =W6 -> M11 | W6: =IF(AND(U6=1,T6=1),"L16",IF(AND(U6=1,T6=2),"L14",IF(AND(U6=1,T6=3),"M11",IF(AND(U6=1,T6=4),"E4",IF(AND(U6=2,T6=1),"L15",IF(AND(U6=2,T6=2),"M12",IF(AND(U6=2,T6=3),"H7",IF(AND(U6=2,T6=4),"E3",IF(AND(U6=3,T6=1),"M13",IF(AND(U6=3,T6=2),"H9",IF(AND(U6=3,T6=3),"E6",IF(AND(U6=4,T6=4),"E2",IF(AND(U6=4,T6=1),"H10",IF(AND(U6=2,T6=4),"H8",IF(AND(U6=4,T6=3),"E5",IF(AND(U6=4,T6=4),"E1",FALSE)))))))))))))))) -> M11
A7: 3 | B7: 1.การผลิตไฟฟ้า | C7: การรับวัตถุดิบ (สารเคมี) | D7: Operational Management | E7: 6.กระบวนการทางธุรกิจและการปฏิบัติการ | G7: 1.ปริมาณสารเคมีไม่พอใช้งาน 2.ถังกักเก็บสารเคมีชำรุดรั่วไหล | H7: 1.1มี On call ผู้จำหน่ายสารเคมี (12 ชม.) 1.2มีการควบคุมปริมาณขั้นต่ำ (Max-Min) สารเคมี 2.1มีกำหนดการตรวจสอบและซ่อมบำรุงถังxxxxx | I7: 3 | J7: 1 | K7: =L7 -> M11 | L7: =IF(AND(J7=1,I7=1),"L16",IF(AND(J7=1,I7=2),"L14",IF(AND(J7=1,I7=3),"M11",IF(AND(J7=1,I7=4),"E4",IF(AND(J7=2,I7=1),"L15",IF(AND(J7=2,I7=2),"M12",IF(AND(J7=2,I7=3),"H7",IF(AND(J7=2,I7=4),"E3",IF(AND(J7=3,I7=1),"M13",IF(AND(J7=3,I7=2),"H9",IF(AND(J7=3,I7=3),"E6",IF(AND(J7=4,I7=4),"E2",IF(AND(J7=4,I7=1),"H10",IF(AND(I7=2,J7=4),"H8",IF(AND(J7=4,I7=3),"E5",IF(AND(J7=4,I7=4),"E1",FALSE)))))))))))))))) -> M11 | M7: ='2.2 BIA Process'!N10 -> 24 ชม | N7: ='2.2 BIA Process'!O10 -> 1 ชม | O7: ='2.2 BIA Process'!P10 -> 1 | P7: 1.จัดหาให้มีระบบถังสารเคมีสำรองเพิ่มอีก 1 ถัง ในการใช้งาน | Q7: Jan | R7: Dec | S7: Operation | T7: 3 | U7: 1 | V7: =W7 -> M11 | W7: =IF(AND(U7=1,T7=1),"L16",IF(AND(U7=1,T7=2),"L14",IF(AND(U7=1,T7=3),"M11",IF(AND(U7=1,T7=4),"E4",IF(AND(U7=2,T7=1),"L15",IF(AND(U7=2,T7=2),"M12",IF(AND(U7=2,T7=3),"H7",IF(AND(U7=2,T7=4),"E3",IF(AND(U7=3,T7=1),"M13",IF(AND(U7=3,T7=2),"H9",IF(AND(U7=3,T7=3),"E6",IF(AND(U7=4,T7=4),"E2",IF(AND(U7=4,T7=1),"H10",IF(AND(U7=2,T7=4),"H8",IF(AND(U7=4,T7=3),"E5",IF(AND(U7=4,T7=4),"E1",FALSE)))))))))))))))) -> M11
A8: 4 | B8: 1.การผลิตไฟฟ้า | C8: การรับวัตถุดิบ (ก๊าซเชื้อเพลิง) | D8: Operational Management | E8: 6.กระบวนการทางธุรกิจและการปฏิบัติการ | G8: 1.ไม่มีก๊าซหรือก๊าซไม่เพียงพอ 2.ท่อส่งเข้าระบบเสียหาย, อุปกรณ์ควบคุมใช้งานไม่ได้ 3.ไฟไหม้ | H8: 1.1มีการตรวจสอบ รายวัน 1.2มีทีมซ่อมบำรุง on call 24 hr 2.1มีการกำหนดแผนซ่อมบำรุงตามระยะเวลากำหนด 2.2มีสัญญาเข้าซ่อมบำรุงระบบ 3.1มีระบบดับเพลิงเครื่องจักร 2 ตัวเพื่อช่วยในการดับเพลิง | I8: 4 | J8: 1 | K8: =L8 -> E4 | L8: =IF(AND(J8=1,I8=1),"L16",IF(AND(J8=1,I8=2),"L14",IF(AND(J8=1,I8=3),"M11",IF(AND(J8=1,I8=4),"E4",IF(AND(J8=2,I8=1),"L15",IF(AND(J8=2,I8=2),"M12",IF(AND(J8=2,I8=3),"H7",IF(AND(J8=2,I8=4),"E3",IF(AND(J8=3,I8=1),"M13",IF(AND(J8=3,I8=2),"H9",IF(AND(J8=3,I8=3),"E6",IF(AND(J8=4,I8=4),"E2",IF(AND(J8=4,I8=1),"H10",IF(AND(I8=2,J8=4),"H8",IF(AND(J8=4,I8=3),"E5",IF(AND(J8=4,I8=4),"E1",FALSE)))))))))))))))) -> E4 | M8: ='2.2 BIA Process'!N11 -> 48 ชม | N8: ='2.2 BIA Process'!O11 -> 1 ชม | O8: ='2.2 BIA Process'!P11 -> 1 | P8: 1.ทำระบบไฟฟ้าส่งจ่ายจาก GLOW,PEA มาจ่ายให้กับลูกค้าแทน 2.ทำระบบท่อไอน้ำจาก GLOW มาจ่ายให้กับลูกค้า | Q8: Jan | R8: Dec | S8: Operation | T8: 3 | U8: 1 | V8: =W8 -> M11 | W8: =IF(AND(U8=1,T8=1),"L16",IF(AND(U8=1,T8=2),"L14",IF(AND(U8=1,T8=3),"M11",IF(AND(U8=1,T8=4),"E4",IF(AND(U8=2,T8=1),"L15",IF(AND(U8=2,T8=2),"M12",IF(AND(U8=2,T8=3),"H7",IF(AND(U8=2,T8=4),"E3",IF(AND(U8=3,T8=1),"M13",IF(AND(U8=3,T8=2),"H9",IF(AND(U8=3,T8=3),"E6",IF(AND(U8=4,T8=4),"E2",IF(AND(U8=4,T8=1),"H10",IF(AND(U8=2,T8=4),"H8",IF(AND(U8=4,T8=3),"E5",IF(AND(U8=4,T8=4),"E1",FALSE)))))))))))))))) -> M11
A9: 5 | B9: 1.การผลิตไฟฟ้า | C9: การรับวัตถุดิบ (น้ำมันเชื้อเพลิงสำหรับระบบดับเพลิง) | D9: Operational Management | E9: 6.กระบวนการทางธุรกิจและการปฏิบัติการ | G9: 1.ปริมาณน้ำมันเชื้อเพลิงไม่พอใช้งาน | H9: 1.มีระบบดับเพลิงเครื่องจักร 2 ตัวเพื่อช่วยในการดับเพลิง 2.มีการซ้อมแผนฉุกเฉินเป็นประจำทุกๆปี 3.มีการตรวจสอบอุปกรณ์เครื่องจักรตามแผนงานซ่อมบำรุงประจำปี | I9: 2 | J9: 2 | K9: =L9 -> M12 | L9: =IF(AND(J9=1,I9=1),"L16",IF(AND(J9=1,I9=2),"L14",IF(AND(J9=1,I9=3),"M11",IF(AND(J9=1,I9=4),"E4",IF(AND(J9=2,I9=1),"L15",IF(AND(J9=2,I9=2),"M12",IF(AND(J9=2,I9=3),"H7",IF(AND(J9=2,I9=4),"E3",IF(AND(J9=3,I9=1),"M13",IF(AND(J9=3,I9=2),"H9",IF(AND(J9=3,I9=3),"E6",IF(AND(J9=4,I9=4),"E2",IF(AND(J9=4,I9=1),"H10",IF(AND(I9=2,J9=4),"H8",IF(AND(J9=4,I9=3),"E5",IF(AND(J9=4,I9=4),"E1",FALSE)))))))))))))))) -> M12 | M9: ='2.2 BIA Process'!N12 -> 48 ชม | N9: ='2.2 BIA Process'!O12 -> 1 ชม | O9: ='2.2 BIA Process'!P12 -> 1 | P9: 1.จัดหาให้มีระบบน้ำมันเชื้อเพลิงสำรองเพิ่ม ในการใช้งาน 2.ติดต่อหน่วยงานที่เกี่ยวข้องเพื่อจัดเตรียมรถดับเพลิงในกรณีฉุกเฉิน (NPCS&E) | Q9: Jan | R9: Dec | S9: SSHE | T9: 1 | U9: 2 | V9: =W9 -> L15 | W9: =IF(AND(U9=1,T9=1),"L16",IF(AND(U9=1,T9=2),"L14",IF(AND(U9=1,T9=3),"M11",IF(AND(U9=1,T9=4),"E4",IF(AND(U9=2,T9=1),"L15",IF(AND(U9=2,T9=2),"M12",IF(AND(U9=2,T9=3),"H7",IF(AND(U9=2,T9=4),"E3",IF(AND(U9=3,T9=1),"M13",IF(AND(U9=3,T9=2),"H9",IF(AND(U9=3,T9=3),"E6",IF(AND(U9=4,T9=4),"E2",IF(AND(U9=4,T9=1),"H10",IF(AND(U9=2,T9=4),"H8",IF(AND(U9=4,T9=3),"E5",IF(AND(U9=4,T9=4),"E1",FALSE)))))))))))))))) -> L15
A10: 6 | B10: 1.การผลิตไฟฟ้า | C10: การรับวัตถุดิบ (ไฟฟ้าสำหรับ Start up process) | D10: Operational Management | E10: 6.กระบวนการทางธุรกิจและการปฏิบัติการ | G10: 1.การผลิตหยุดชะงักเนื่องจากไม่มีกระแสไฟฟ้า 2.ไม่สามารถ Start กระบวนการผลิตได้กรณีที่สายส่ง EGAT/ PEA ชำรุดส่งผลให้ Plant Blackout | H10: 1.1มีสัญญาการรับไฟฟ้าจากการไฟฟ้า 2.1จัดทำแผนซ่อมบำรุง อุปกรณ์ตามระยะเวลาที่กำหนด 2.2มีทีม on call ซ่อมบำรุง 24 ชม. | I10: 3 | J10: 1 | K10: =L10 -> M11 | L10: =IF(AND(J10=1,I10=1),"L16",IF(AND(J10=1,I10=2),"L14",IF(AND(J10=1,I10=3),"M11",IF(AND(J10=1,I10=4),"E4",IF(AND(J10=2,I10=1),"L15",IF(AND(J10=2,I10=2),"M12",IF(AND(J10=2,I10=3),"H7",IF(AND(J10=2,I10=4),"E3",IF(AND(J10=3,I10=1),"M13",IF(AND(J10=3,I10=2),"H9",IF(AND(J10=3,I10=3),"E6",IF(AND(J10=4,I10=4),"E2",IF(AND(J10=4,I10=1),"H10",IF(AND(I10=2,J10=4),"H8",IF(AND(J10=4,I10=3),"E5",IF(AND(J10=4,I10=4),"E1",FALSE)))))))))))))))) -> M11 | M10: ='2.2 BIA Process'!N13 -> 24 ชม | N10: ='2.2 BIA Process'!O13 -> 1 ชม | O10: ='2.2 BIA Process'!P13 -> 1 | P10: 1.ศึกษาการจัดหาแหล่งไฟฟ้าสำรองในการ Start plant จากแหล่งอื่น เช่น Diesel GEN. 2.ศึกษาการเชื่อมต่อระบบกับ Glow ในการ Charge Back | Q10: Jan | R10: Dec | S10: Engineering | T10: 2 | U10: 1 | V10: =W10 -> L14 | W10: =IF(AND(U10=1,T10=1),"L16",IF(AND(U10=1,T10=2),"L14",IF(AND(U10=1,T10=3),"M11",IF(AND(U10=1,T10=4),"E4",IF(AND(U10=2,T10=1),"L15",IF(AND(U10=2,T10=2),"M12",IF(AND(U10=2,T10=3),"H7",IF(AND(U10=2,T10=4),"E3",IF(AND(U10=3,T10=1),"M13",IF(AND(U10=3,T10=2),"H9",IF(AND(U10=3,T10=3),"E6",IF(AND(U10=4,T10=4),"E2",IF(AND(U10=4,T10=1),"H10",IF(AND(U10=2,T10=4),"H8",IF(AND(U10=4,T10=3),"E5",IF(AND(U10=4,T10=4),"E1",FALSE)))))))))))))))) -> L14
A11: 7 | B11: 1.การผลิตไฟฟ้า | C11: เดินเครื่องระบบ BOP (Cooling, Air Compressor ) | D11: Operational Management | E11: 6.กระบวนการทางธุรกิจและการปฏิบัติการ | G11: 1. การผลิตหยุดเนื่องจากไม่มีกระแสไฟฟ้า 2.การผลิตหยุดเนื่องจากไม่มีน้ำ | H11: 1.1มีระบบ อัตโนมัติควบคุม 2 ตัวขึ้นไปในการใช้งานกระบวนการผลิต 1.2มีระบบ by pass 1.3มีระบบควบคุมอัตโนมัติ (Emergency) และระบบป้องกันอุปกรณ์(Protection)) เพื่อป้องกันเครื่องจักรเสียหาย 1.4มีการติดตั้งอุปกรณ์สำรอง 1.5มีแผนซ่อมบำรุงรักษาประจำปี/ ประจำเดือน 2.1มีการจด log sheet เพื่อประเมินค่าของอุปกรณ์ว่าผิดปกติหรือไม่และ Visual check ขณะทำการจด log sheet | I11: 3 | J11: 1 | K11: =L11 -> M11 | L11: =IF(AND(J11=1,I11=1),"L16",IF(AND(J11=1,I11=2),"L14",IF(AND(J11=1,I11=3),"M11",IF(AND(J11=1,I11=4),"E4",IF(AND(J11=2,I11=1),"L15",IF(AND(J11=2,I11=2),"M12",IF(AND(J11=2,I11=3),"H7",IF(AND(J11=2,I11=4),"E3",IF(AND(J11=3,I11=1),"M13",IF(AND(J11=3,I11=2),"H9",IF(AND(J11=3,I11=3),"E6",IF(AND(J11=4,I11=4),"E2",IF(AND(J11=4,I11=1),"H10",IF(AND(I11=2,J11=4),"H8",IF(AND(J11=4,I11=3),"E5",IF(AND(J11=4,I11=4),"E1",FALSE)))))))))))))))) -> M11 | M11: ='2.2 BIA Process'!N14 -> 7 วัน | N11: ='2.2 BIA Process'!O14 -> 7 วัน | O11: ='2.2 BIA Process'!P14 -> 1 | P11: 1.สำรองติดตั้ง Mobile Air compressor ชั่วคราวโดยทำสัญญากับ Supplier | Q11: Jan | R11: Dec | S11: Maintenance | T11: 1 | U11: 1 | V11: =W11 -> L16 | W11: =IF(AND(U11=1,T11=1),"L16",IF(AND(U11=1,T11=2),"L14",IF(AND(U11=1,T11=3),"M11",IF(AND(U11=1,T11=4),"E4",IF(AND(U11=2,T11=1),"L15",IF(AND(U11=2,T11=2),"M12",IF(AND(U11=2,T11=3),"H7",IF(AND(U11=2,T11=4),"E3",IF(AND(U11=3,T11=1),"M13",IF(AND(U11=3,T11=2),"H9",IF(AND(U11=3,T11=3),"E6",IF(AND(U11=4,T11=4),"E2",IF(AND(U11=4,T11=1),"H10",IF(AND(U11=2,T11=4),"H8",IF(AND(U11=4,T11=3),"E5",IF(AND(U11=4,T11=4),"E1",FALSE)))))))))))))))) -> L16
A12: 8 | B12: 1.การผลิตไฟฟ้า | C12: เดินเครื่องระบบ Fuel Gas | D12: Operational Management | E12: 6.กระบวนการทางธุรกิจและการปฏิบัติการ | G12: 1.ไม่สามารถเดินเครื่องได้เนื่องจากไม่มีก๊าซทำให้ระบบเครื่องจักรการผลิตหยุดชะงัก | H12: 1.1 มีแผนซ่อมบำรุงรักษาประจำปี/ ประจำเดือน 1.2 มีการติดตั้งอุปกรณ์สำรอง 1.3 มีการจด log sheet เพื่อประเมินค่าของอุปกรณ์ว่าผิดปกติหรือไม่และ Visual check ขณะทำการจด log sheet | I12: 4 | J12: 2 | K12: =L12 -> E3 | L12: =IF(AND(J12=1,I12=1),"L16",IF(AND(J12=1,I12=2),"L14",IF(AND(J12=1,I12=3),"M11",IF(AND(J12=1,I12=4),"E4",IF(AND(J12=2,I12=1),"L15",IF(AND(J12=2,I12=2),"M12",IF(AND(J12=2,I12=3),"H7",IF(AND(J12=2,I12=4),"E3",IF(AND(J12=3,I12=1),"M13",IF(AND(J12=3,I12=2),"H9",IF(AND(J12=3,I12=3),"E6",IF(AND(J12=4,I12=4),"E2",IF(AND(J12=4,I12=1),"H10",IF(AND(I12=2,J12=4),"H8",IF(AND(J12=4,I12=3),"E5",IF(AND(J12=4,I12=4),"E1",FALSE)))))))))))))))) -> E3 | M12: ='2.2 BIA Process'!N15 -> 7 วัน | N12: ='2.2 BIA Process'!O15 -> 7 วัน | O12: ='2.2 BIA Process'!P15 -> 1 | P12: 1.ให้มีทีมซ่อมบำรุง และชิ้นส่วนอะไหล่ ตลอด24 ชม. เพื่อไม่ต้องเสียเวลาในการรอคอย ในขณะที่ตาม oncall | Q12: Jan | R12: Dec | S12: Maintenance | T12: 3 | U12: 2 | V12: =W12 -> H7 | W12: =IF(AND(U12=1,T12=1),"L16",IF(AND(U12=1,T12=2),"L14",IF(AND(U12=1,T12=3),"M11",IF(AND(U12=1,T12=4),"E4",IF(AND(U12=2,T12=1),"L15",IF(AND(U12=2,T12=2),"M12",IF(AND(U12=2,T12=3),"H7",IF(AND(U12=2,T12=4),"E3",IF(AND(U12=3,T12=1),"M13",IF(AND(U12=3,T12=2),"H9",IF(AND(U12=3,T12=3),"E6",IF(AND(U12=4,T12=4),"E2",IF(AND(U12=4,T12=1),"H10",IF(AND(U12=2,T12=4),"H8",IF(AND(U12=4,T12=3),"E5",IF(AND(U12=4,T12=4),"E1",FALSE)))))))))))))))) -> H7
A13: 9 | B13: 1.การผลิตไฟฟ้า | C13: เดินเครื่องระบบ Demin, Condensate และ Neutralization. | D13: Operational Management | E13: 6.กระบวนการทางธุรกิจและการปฏิบัติการ | G13: 1.ไม่สามารถผลิตน้ำ Demin ได้เนื่องจากไม่มีกระแสไฟฟ้า 2.ปริมาณน้ำ Demin ไม่เพียงพอต่อการใช้งานในการบวนการผลิตและส่งให้ลูกค้าได้ | H13: 1.1มีการติดตั้งระบบสำรองในการผลิตนำ Demin 4 units, Condensate 2 units. 1.2ระบบ Pump Neutralization มี 2 unit สามารถได้สลับกันได้กรณีอีกตัวเสีย 2.1มีระบบนำ RO เพิ่มอีก 2 units ในกระบวนการผลิตเพื่อช่วยผลิตน้ำได้ 2.2รับน้ำ Demin จาก WHA | I13: 3 | J13: 1 | K13: =L13 -> M11 | L13: =IF(AND(J13=1,I13=1),"L16",IF(AND(J13=1,I13=2),"L14",IF(AND(J13=1,I13=3),"M11",IF(AND(J13=1,I13=4),"E4",IF(AND(J13=2,I13=1),"L15",IF(AND(J13=2,I13=2),"M12",IF(AND(J13=2,I13=3),"H7",IF(AND(J13=2,I13=4),"E3",IF(AND(J13=3,I13=1),"M13",IF(AND(J13=3,I13=2),"H9",IF(AND(J13=3,I13=3),"E6",IF(AND(J13=4,I13=4),"E2",IF(AND(J13=4,I13=1),"H10",IF(AND(I13=2,J13=4),"H8",IF(AND(J13=4,I13=3),"E5",IF(AND(J13=4,I13=4),"E1",FALSE)))))))))))))))) -> M11 | M13: ='2.2 BIA Process'!N16 -> 7 วัน | N13: ='2.2 BIA Process'!O16 -> 7 วัน | O13: ='2.2 BIA Process'!P16 -> 1 | P13: 1.พิจารณาหาแหล่งน้ำสำรอง เช่น รถขนส่ง 2.จัดหาแหล่งน้ำสำรองจากแหล่งอื่นๆ เช่น เชื่อมระบบกับ Glow & CUP3 | Q13: Jan | R13: Dec | S13: Operation | T13: 2 | U13: 1 | V13: =W13 -> L14 | W13: =IF(AND(U13=1,T13=1),"L16",IF(AND(U13=1,T13=2),"L14",IF(AND(U13=1,T13=3),"M11",IF(AND(U13=1,T13=4),"E4",IF(AND(U13=2,T13=1),"L15",IF(AND(U13=2,T13=2),"M12",IF(AND(U13=2,T13=3),"H7",IF(AND(U13=2,T13=4),"E3",IF(AND(U13=3,T13=1),"M13",IF(AND(U13=3,T13=2),"H9",IF(AND(U13=3,T13=3),"E6",IF(AND(U13=4,T13=4),"E2",IF(AND(U13=4,T13=1),"H10",IF(AND(U13=2,T13=4),"H8",IF(AND(U13=4,T13=3),"E5",IF(AND(U13=4,T13=4),"E1",FALSE)))))))))))))))) -> L14
A14: 10 | B14: 1.การผลิตไฟฟ้า | C14: เดินเครื่องระบบ BFW และ Deaerator | D14: Operational Management | E14: 6.กระบวนการทางธุรกิจและการปฏิบัติการ | G14: 1. ไม่สามารถเดินระบบได้เนื่องจากไม่มีกระแสไฟฟ้า 2.การผลิตหยุดเนื่องจากไม่มีน้ำ | H14: 1.1xxxxx 2.1xxxxx | I14: 4 | J14: 1 | K14: =L14 -> E4 | L14: =IF(AND(J14=1,I14=1),"L16",IF(AND(J14=1,I14=2),"L14",IF(AND(J14=1,I14=3),"M11",IF(AND(J14=1,I14=4),"E4",IF(AND(J14=2,I14=1),"L15",IF(AND(J14=2,I14=2),"M12",IF(AND(J14=2,I14=3),"H7",IF(AND(J14=2,I14=4),"E3",IF(AND(J14=3,I14=1),"M13",IF(AND(J14=3,I14=2),"H9",IF(AND(J14=3,I14=3),"E6",IF(AND(J14=4,I14=4),"E2",IF(AND(J14=4,I14=1),"H10",IF(AND(I14=2,J14=4),"H8",IF(AND(J14=4,I14=3),"E5",IF(AND(J14=4,I14=4),"E1",FALSE)))))))))))))))) -> E4 | M14: ='2.2 BIA Process'!N17 -> 7 วัน | N14: ='2.2 BIA Process'!O17 -> 7 วัน | O14: ='2.2 BIA Process'!P17 -> 1 | P14: 1.ให้มีทีมซ่อมบำรุง และชิ้นส่วนอะไหล่ ตลอด24 ชม. เพื่อไม่ต้องเสียเวลาในการรอคอย ในขณะที่ตาม oncall 2.หาแหล่งน้ำอื่นๆเช่น BFW จาก CUP3 ส่งให้ลูกค้าแทนได้ | Q14: Jan | R14: Dec | S14: Maintenance | T14: 3 | U14: 1 | V14: =W14 -> M11 | W14: =IF(AND(U14=1,T14=1),"L16",IF(AND(U14=1,T14=2),"L14",IF(AND(U14=1,T14=3),"M11",IF(AND(U14=1,T14=4),"E4",IF(AND(U14=2,T14=1),"L15",IF(AND(U14=2,T14=2),"M12",IF(AND(U14=2,T14=3),"H7",IF(AND(U14=2,T14=4),"E3",IF(AND(U14=3,T14=1),"M13",IF(AND(U14=3,T14=2),"H9",IF(AND(U14=3,T14=3),"E6",IF(AND(U14=4,T14=4),"E2",IF(AND(U14=4,T14=1),"H10",IF(AND(U14=2,T14=4),"H8",IF(AND(U14=4,T14=3),"E5",IF(AND(U14=4,T14=4),"E1",FALSE)))))))))))))))) -> M11
A15: 11 | B15: 2.การผลิตไอน้ำ | C15: เดินเครื่อง Aux Boiler , HRSG และ Emission Control. | D15: Operational Management | E15: 6.กระบวนการทางธุรกิจและการปฏิบัติการ | G15: 1. การผลิตไอน้ำหยุดเนื่องจากไม่มีกระแสไฟฟ้า 2.การผลิตไอน้ำหยุดเนื่องจากไม่มีน้ำ 3.การผลิตไอน้ำหยุดเนื่องจากไม่มีเชื้อเพลิง 4.การผลิตไอน้ำหยุดเนื่องจากปริมาณสารเคมีไม่พอใช้งาน 5.ไม่สอดคล้องตามกฏหมาย ค่า Emission เกินมาตราฐาน เนื่องจากไม่มีสารเคมีใช้ในกระบวนการผลิต (No chemical) | H15: 1.1มีสัญญาการรับไฟฟ้าจากการไฟฟ้า 2.1xxxx 3.1xxxxx 4.1มี On call ผู้จำหน่ายสารเคมี (12 ชม.) 4.2มีการควบคุมปริมาณขั้นต่ำ (Max-Min) สารเคมี 5.1 มีระบบควบคุม Emission และระบบเตือนเมื่อค่าเกิดค่าที่ควบคุม | I15: 3 | J15: 2 | K15: =L15 -> H7 | L15: =IF(AND(J15=1,I15=1),"L16",IF(AND(J15=1,I15=2),"L14",IF(AND(J15=1,I15=3),"M11",IF(AND(J15=1,I15=4),"E4",IF(AND(J15=2,I15=1),"L15",IF(AND(J15=2,I15=2),"M12",IF(AND(J15=2,I15=3),"H7",IF(AND(J15=2,I15=4),"E3",IF(AND(J15=3,I15=1),"M13",IF(AND(J15=3,I15=2),"H9",IF(AND(J15=3,I15=3),"E6",IF(AND(J15=4,I15=4),"E2",IF(AND(J15=4,I15=1),"H10",IF(AND(I15=2,J15=4),"H8",IF(AND(J15=4,I15=3),"E5",IF(AND(J15=4,I15=4),"E1",FALSE)))))))))))))))) -> H7 | M15: ='2.2 BIA Process'!N18 -> 7 วัน | N15: ='2.2 BIA Process'!O18 -> 7 วัน | O15: ='2.2 BIA Process'!P18 -> 1 | P15: 1.ให้มีทีมซ่อมบำรุง และชิ้นส่วนอะไหล่ ตลอด24 ชม. เพื่อไม่ต้องเสียเวลาในการรอคอย ในขณะที่ตาม oncall 2.หาแหล่งไอน้ำอื่นๆ เช่น รับจาก CUP3,CUP4&GLOW ส่งให้ลูกค้าแทนได้ | Q15: Jan | R15: Dec | S15: Maintenance | T15: 2 | U15: 2 | V15: =W15 -> M12 | W15: =IF(AND(U15=1,T15=1),"L16",IF(AND(U15=1,T15=2),"L14",IF(AND(U15=1,T15=3),"M11",IF(AND(U15=1,T15=4),"E4",IF(AND(U15=2,T15=1),"L15",IF(AND(U15=2,T15=2),"M12",IF(AND(U15=2,T15=3),"H7",IF(AND(U15=2,T15=4),"E3",IF(AND(U15=3,T15=1),"M13",IF(AND(U15=3,T15=2),"H9",IF(AND(U15=3,T15=3),"E6",IF(AND(U15=4,T15=4),"E2",IF(AND(U15=4,T15=1),"H10",IF(AND(U15=2,T15=4),"H8",IF(AND(U15=4,T15=3),"E5",IF(AND(U15=4,T15=4),"E1",FALSE)))))))))))))))) -> M12
